<?xml version="1.0" ?>
<!-- =================================================================================== -->
<!-- |    This document was autogenerated by xacro from /home/stickbug/workspace-stickbug/src/stickbug/robot-stickbug/stickbug/urdf/stickbug.urdf.xacro | -->
<!-- |    EDITING THIS FILE BY HAND IS NOT RECOMMENDED                                 | -->
<!-- =================================================================================== -->
<robot name="stickbug">
    <link name="stickbug/drivebase/base_footprint">
        <inertial>
            <origin rpy="0 0 0" xyz="2.14152041306814E-05 3.23189598462186E-05 0.066675" />
            <mass value="4.61207520224653" />
            <inertia ixx="0.0999230513061692" ixy="2.56363639829506E-06" ixz="-1.98809620225214E-19" iyy="0.0999410253939969" iyz="6.92922956199162E-20" izz="0.199833081633109" />
        </inertial>
        <visual>
            <origin rpy="0 0 0" xyz="0 0 0" />
            <geometry>
                <mesh filename="package://stickbug_base/meshes/base_footprint.STL" />
            </geometry>
            <material name="">
                <color rgba="0.898039215686275 0.917647058823529 0.929411764705882 1" />
            </material>
        </visual>
        <collision>
            <origin rpy="0 0 0" xyz="0 0 0" />
            <geometry>
                <mesh filename="package://stickbug_base/meshes/base_footprint.STL" />
            </geometry>
        </collision>
    </link>
    <link name="stickbug/drivebase/base_link">
        <inertial>
            <origin rpy="0 0 0" xyz="0.0102079284624479 -3.86323815662623E-05 0.201127610999515" />
            <mass value="35.0775372153667" />
            <inertia ixx="0.845153226678831" ixy="1.15795308289346E-06" ixz="-4.72502983562422E-06" iyy="0.857016820744041" iyz="-1.46341439248048E-08" izz="0.4330698567729" />
        </inertial>
        <visual>
            <origin rpy="0 0 0" xyz="0 0 0" />
            <geometry>
                <mesh filename="package://stickbug_base/meshes/base_link.STL" />
            </geometry>
            <material name="">
                <color rgba="0.109803921568627 0.109803921568627 0.109803921568627 1" />
            </material>
        </visual>
        <collision>
            <origin rpy="0 0 0" xyz="0 0 0" />
            <geometry>
                <mesh filename="package://stickbug_base/meshes/base_link.STL" />
            </geometry>
        </collision>
    </link>
    <joint name="stickbug/drivebase/foot2base" type="fixed">
        <origin rpy="0 0 0" xyz="2.1415E-05 3.2319E-05 0.0635" />
        <parent link="stickbug/drivebase/base_footprint" />
        <child link="stickbug/drivebase/base_link" />
        <axis xyz="0 0 0" />
    </joint>
    <link name="stickbug/drivebase/fr_wheel">
        <inertial>
            <origin rpy="0 0 0" xyz="4.82958464445016E-05 -7.32604728410462E-05 -0.0158742308710669" />
            <mass value="0.626653098801925" />
            <inertia ixx="0.00071178175395083" ixy="2.7414822166393E-09" ixz="-5.77419111548287E-08" iyy="0.000711774501854219" iyz="7.87863202048541E-08" izz="0.00139769373829352" />
        </inertial>
        <visual>
            <origin rpy="0 0 0" xyz="0 0 0" />
            <geometry>
                <mesh filename="package://stickbug_base/meshes/fr_wheel.STL" />
            </geometry>
            <material name="">
                <color rgba="0.792156862745098 0.819607843137255 0.933333333333333 1" />
            </material>
        </visual>
        <collision>
            <origin rpy="0 0 0" xyz="0 0 0" />
            <geometry>
                <mesh filename="package://stickbug_base/meshes/fr_wheel.STL" />
            </geometry>
        </collision>
    </link>
    <joint name="stickbug/drivebase/frw" type="continuous">
        <origin rpy="1.5708 0 0.5236" xyz="0.16059 -0.27821 0.0381" />
        <parent link="stickbug/drivebase/base_link" />
        <child link="stickbug/drivebase/fr_wheel" />
        <axis xyz="0 0 1" />
        <limit effort="10.0" velocity="10" />
        <dynamics damping="0.2" />
    </joint>
    <link name="stickbug/drivebase/fl_wheel">
        <inertial>
            <origin rpy="0 0 0" xyz="-7.20537664984366E-05 -6.99681935735462E-05 -0.0152708692239969" />
            <mass value="0.559485027704479" />
            <inertia ixx="0.000579784098176026" ixy="-1.88505640148465E-09" ixz="6.17916644106062E-08" iyy="0.000579785178714697" iyz="7.56495525234232E-08" izz="0.0011338073867259" />
        </inertial>
        <visual>
            <origin rpy="0 0 0" xyz="0 0 0" />
            <geometry>
                <mesh filename="package://stickbug_base/meshes/fl_wheel.STL" />
            </geometry>
            <material name="">
                <color rgba="0.792156862745098 0.819607843137255 0.933333333333333 1" />
            </material>
        </visual>
        <collision>
            <origin rpy="0 0 0" xyz="0 0 0" />
            <geometry>
                <mesh filename="package://stickbug_base/meshes/fl_wheel.STL" />
            </geometry>
        </collision>
    </link>
    <joint name="stickbug/drivebase/flw" type="continuous">
        <origin rpy="1.5708 0 2.618" xyz="0.16059 0.27815 0.0381" />
        <parent link="stickbug/drivebase/base_link" />
        <child link="stickbug/drivebase/fl_wheel" />
        <axis xyz="0 0 1" />
        <limit effort="10.0" velocity="10" />
        <dynamics damping="0.2" />
    </joint>
    <link name="stickbug/drivebase/b_wheel">
        <inertial>
            <origin rpy="0 0 0" xyz="8.36992519676054E-05 -2.63433393755813E-05 -0.0158742295235679" />
            <mass value="0.626653031138758" />
            <inertia ixx="0.00071177618338088" ixy="4.1083335760656E-09" ixz="-9.45107850065779E-08" iyy="0.000711780076798303" iyz="2.46679649776571E-08" izz="0.00139769373928287" />
        </inertial>
        <visual>
            <origin rpy="0 0 0" xyz="0 0 0" />
            <geometry>
                <mesh filename="package://stickbug_base/meshes/b_wheel.STL" />
            </geometry>
            <material name="">
                <color rgba="0.792156862745098 0.819607843137255 0.933333333333333 1" />
            </material>
        </visual>
        <collision>
            <origin rpy="0 0 0" xyz="0 0 0" />
            <geometry>
                <mesh filename="package://stickbug_base/meshes/b_wheel.STL" />
            </geometry>
        </collision>
    </link>
    <joint name="stickbug/drivebase/bw" type="continuous">
        <origin rpy="1.5708 0 -1.5708" xyz="-0.32124 -3.2319E-05 0.0381" />
        <parent link="stickbug/drivebase/base_link" />
        <child link="stickbug/drivebase/b_wheel" />
        <axis xyz="0 0 1" />
        <limit effort="10.0" velocity="10" />
        <dynamics damping="0.2" />
    </joint>
    <link name="stickbug/drivebase/lidar">
        <inertial>
            <origin rpy="0 0 0" xyz="-9.78202271295636E-05 -2.43039787231798E-06 0.0058316040170599" />
            <mass value="0.6957286087788" />
            <inertia ixx="0.000878507722123655" ixy="8.3578146326656E-11" ixz="8.3324695920418E-08" iyy="0.000878975923859681" iyz="-6.86791280845821E-08" izz="0.000889858414455019" />
        </inertial>
        <visual>
            <origin rpy="0 0 0" xyz="0 0 0" />
            <geometry>
                <mesh filename="package://stickbug_base/meshes/lidar.STL" />
            </geometry>
            <material name="">
                <color rgba="0.752941176470588 0.752941176470588 0.752941176470588 1" />
            </material>
        </visual>
        <collision>
            <origin rpy="0 0 0" xyz="0 0 0" />
            <geometry>
                <mesh filename="package://stickbug_base/meshes/lidar.STL" />
            </geometry>
        </collision>
    </link>
    <joint name="stickbug/drivebase/base2lidar" type="fixed">
        <origin rpy="0 0 0" xyz="0.21804 -3.2319E-05 0.32913" />
        <parent link="stickbug/drivebase/base_link" />
        <child link="stickbug/drivebase/lidar" />
        <axis xyz="0 0 0" />
    </joint>
    <link name="stickbug/drivebase/zed">
        <inertial>
            <origin rpy="0 0 0" xyz="-0.0194322614660269 9.12426059709588E-07 -0.000862607518043401" />
            <mass value="0.167694642835054" />
            <inertia ixx="0.000382844282483195" ixy="3.2315292808456E-09" ixz="-3.326725690359E-07" iyy="3.24806894733853E-05" iyz="1.49948250317334E-09" izz="0.000390509177129988" />
        </inertial>
        <visual>
            <origin rpy="0 0 0" xyz="0 0 0" />
            <geometry>
                <mesh filename="package://stickbug_base/meshes/zed.STL" />
            </geometry>
            <material name="">
                <color rgba="0.792156862745098 0.819607843137255 0.933333333333333 1" />
            </material>
        </visual>
        <collision>
            <origin rpy="0 0 0" xyz="0 0 0" />
            <geometry>
                <mesh filename="package://stickbug_base/meshes/zed.STL" />
            </geometry>
        </collision>
    </link>
    <joint name="stickbug/drivebase/base2zed" type="fixed">
        <origin rpy="0 0.034907 0" xyz="0.30283 -3.2319E-05 0.23593" />
        <parent link="stickbug/drivebase/base_link" />
        <child link="stickbug/drivebase/zed" />
        <axis xyz="0 0 0" />
    </joint>
    <link name="stickbug/drivebase/d355">
        <inertial>
            <origin rpy="0 0 0" xyz="-0.00788625798889209 -0.000593104662498781 9.05379812177198E-05" />
            <mass value="0.061436017794559" />
            <inertia ixx="5.89869602274054E-05" ixy="-1.96801347845483E-08" ixz="-2.7110431537758E-08" iyy="4.49845717604606E-06" iyz="1.96478787836703E-08" izz="5.57860158775296E-05" />
        </inertial>
        <visual>
            <origin rpy="0 0 0" xyz="0 0 0" />
            <geometry>
                <mesh filename="package://stickbug_base/meshes/d355.STL" />
            </geometry>
            <material name="">
                <color rgba="0.792156862745098 0.819607843137255 0.933333333333333 1" />
            </material>
        </visual>
        <collision>
            <origin rpy="0 0 0" xyz="0 0 0" />
            <geometry>
                <mesh filename="package://stickbug_base/meshes/d355.STL" />
            </geometry>
        </collision>
    </link>
    <joint name="stickbug/drivebase/base2d355" type="fixed">
        <origin rpy="3.1416 1.5708 0" xyz="-0.0035667 -3.2319E-05 1.8093" />
        <!-- 0 3.1416 -1.5708-->
        <parent link="stickbug/drivebase/base_link" />
        <child link="stickbug/drivebase/d355" />
        <axis xyz="0 0 0" />
    </joint>
    <link name="stickbug/drivebase/l_lift">
        <inertial>
            <origin rpy="0 0 0" xyz="0.000290120193721988 -3.98269065002427E-05 -0.0130757720478314" />
            <mass value="0.0129866178194594" />
            <inertia ixx="1.43164773219033E-06" ixy="2.3850396902316E-09" ixz="-1.65543141791114E-08" iyy="1.44873230959085E-06" iyz="2.27143690223563E-09" izz="2.11753052630025E-06" />
        </inertial>
        <visual>
            <origin rpy="0 0 0" xyz="0 0 0" />
            <geometry>
                <mesh filename="package://stickbug_base/meshes/l_lift.STL" />
            </geometry>
            <material name="">
                <color rgba="0.752941176470588 0.752941176470588 0.752941176470588 1" />
            </material>
        </visual>
        <collision>
            <origin rpy="0 0 0" xyz="0 0 0" />
            <geometry>
                <mesh filename="package://stickbug_base/meshes/l_lift.STL" />
            </geometry>
        </collision>
    </link>
    <joint name="stickbug/drivebase/base2l_lift" type="fixed">
        <origin rpy="0 0 0" xyz="0.12397 0.094788 0.32988" />
        <parent link="stickbug/drivebase/base_link" />
        <child link="stickbug/drivebase/l_lift" />
        <axis xyz="0 0 0" />
    </joint>
    <link name="stickbug/drivebase/r_lift">
        <inertial>
            <origin rpy="0 0 0" xyz="0.00029284109815797 -2.274392613133E-08 -0.013075772047841" />
            <mass value="0.0129866178194594" />
            <inertia ixx="1.43132102452946E-06" ixy="-3.75614859620096E-12" ixz="-1.67094208007256E-08" iyy="1.44905901725174E-06" iyz="2.13866775789404E-13" izz="2.11753052630024E-06" />
        </inertial>
        <visual>
            <origin rpy="0 0 0" xyz="0 0 0" />
            <geometry>
                <mesh filename="package://stickbug_base/meshes/r_lift.STL" />
            </geometry>
            <material name="">
                <color rgba="0.752941176470588 0.752941176470588 0.752941176470588 1" />
            </material>
        </visual>
        <collision>
            <origin rpy="0 0 0" xyz="0 0 0" />
            <geometry>
                <mesh filename="package://stickbug_base/meshes/r_lift.STL" />
            </geometry>
        </collision>
    </link>
    <joint name="stickbug/drivebase/base2r_lift" type="fixed">
        <origin rpy="0 0 0" xyz="0.12379 -0.095217 0.32988" />
        <parent link="stickbug/drivebase/base_link" />
        <child link="stickbug/drivebase/r_lift" />
        <axis xyz="0 0 0" />
    </joint>
    <link name="stickbug/drivebase/camera_frame" />
    <joint name="stickbug/drivebase/d3552cam" type="fixed">
        <parent link="stickbug/drivebase/d355" />
        <child link="stickbug/drivebase/camera_frame" />
        <origin rpy="-1.57 0.0 -1.57" xyz="0.0 0.0 0.0" />
    </joint>
    <!-- ================================= motor joint controllers ==========================-->
    <transmission name="stickbug/drivebase/trans_frw">
        <type>transmission_interface/SimpleTransmission</type>
        <joint name="stickbug/drivebase/frw">
            <hardwareInterface>hardware_interface/EffortJointInterface</hardwareInterface>
        </joint>
        <actuator name="stickbug/drivebase/frw_motor">
            <hardwareInterface>hardware_interface/EffortJointInterface</hardwareInterface>
            <mechanicalReduction>1</mechanicalReduction>
        </actuator>
    </transmission>
    <transmission name="stickbug/drivebase/trans_flw">
        <type>transmission_interface/SimpleTransmission</type>
        <joint name="stickbug/drivebase/flw">
            <hardwareInterface>hardware_interface/EffortJointInterface</hardwareInterface>
        </joint>
        <actuator name="stickbug/drivebase/flw_motor">
            <hardwareInterface>hardware_interface/EffortJointInterface</hardwareInterface>
            <mechanicalReduction>1</mechanicalReduction>
        </actuator>
    </transmission>
    <transmission name="stickbug/drivebase/trans_bw">
        <type>transmission_interface/SimpleTransmission</type>
        <joint name="stickbug/drivebase/bw">
            <hardwareInterface>hardware_interface/EffortJointInterface</hardwareInterface>
        </joint>
        <actuator name="stickbug/drivebase/bw_motor">
            <hardwareInterface>hardware_interface/EffortJointInterface</hardwareInterface>
            <mechanicalReduction>1</mechanicalReduction>
        </actuator>
    </transmission>
    <!--=============================== holonomic drivetrain plugin ==========================-->
    <gazebo>
        <plugin filename="libgazebo_ros_planar_move.so" name="stickbug/drivebase/object_controller">
            <commandTopic>stickbug/drivebase/cmd_vel</commandTopic>
            <odometryTopic>stickbug/drivebase/odom</odometryTopic>
            <odometryFrame>odom</odometryFrame>
            <odometryRate>20.0</odometryRate>
            <robotBaseFrame>stickbug/drivebase/base_footprint</robotBaseFrame>
        </plugin>
        <plugin name="gazebo_ros_control">
            <robotNamespace>/</robotNamespace>
        </plugin>
    </gazebo>
    <!--================================ realsense plugin ================================-->
    <gazebo reference="stickbug/drivebase/d355">
        <sensor name="stickbug/drivebase/d355_camera" type="depth">
            <update_rate>20</update_rate>
            <camera>
                <horizontal_fov>1.047198</horizontal_fov>
                <image>
                    <width>640</width>
                    <height>480</height>
                    <format>R8G8B8</format>
                </image>
                <clip>
                    <near>0.05</near>
                    <far>3</far>
                </clip>
            </camera>
            <plugin filename="libgazebo_ros_openni_kinect.so" name="stickbug/drivebase/d355_controller">
                <baseline>0.2</baseline>
                <alwaysOn>true</alwaysOn>
                <updateRate>1.0</updateRate>
                <cameraName>stickbug/drivebase/d355</cameraName>
                <imageTopicName>color/image_raw</imageTopicName>
                <cameraInfoTopicName>color/camera_info</cameraInfoTopicName>
                <depthImageTopicName>depth/image_raw</depthImageTopicName>
                <depthImageInfoTopicName>depth/camera_info</depthImageInfoTopicName>
                <pointCloudTopicName>depth/points</pointCloudTopicName>
                <frameName>stickbug/drivebase/camera_frame</frameName>
                <pointCloudCutoff>0.5</pointCloudCutoff>
                <pointCloudCutoffMax>3.0</pointCloudCutoffMax>
                <distortionK1>0.00000001</distortionK1>
                <distortionK2>0.00000001</distortionK2>
                <distortionK3>0.00000001</distortionK3>
                <distortionT1>0.00000001</distortionT1>
                <distortionT2>0.00000001</distortionT2>
                <CxPrime>0</CxPrime>
                <Cx>0</Cx>
                <Cy>0</Cy>
                <focalLength>0</focalLength>
                <hackBaseline>0</hackBaseline>
            </plugin>
        </sensor>
    </gazebo>
    <!--================================ lidar plugin ============================================-->
    <gazebo reference="stickbug/drivebase/lidar">
        <sensor name="sonar" type="ray">
            <pose>0.0 0.0 0.0 0.0 0.0 0.0</pose>
            <ray>
                <scan>
                    <horizontal>
                        <samples>360</samples>
                        <resolution>1.0</resolution>
                        <min_angle>-3.14</min_angle>
                        <max_angle>3.14</max_angle>
                    </horizontal>
                    <vertical>
                        <samples>32</samples>
                        <resolution>1.0</resolution>
                        <min_angle>-0.7854</min_angle>
                        <max_angle>0.7854</max_angle>
                    </vertical>
                </scan>
                <range>
                    <min>0.2</min>
                    <max>50.0</max>
                </range>
            </ray>
            <plugin filename="libgazebo_ros_block_laser.so" name="sonar_plugin">
                <gaussianNoise>0.00</gaussianNoise>
                <alwaysOn>true</alwaysOn>
                <updateRate>100.0</updateRate>
                <topicName>stickbug/drivebase/points</topicName>
                <frameName>stickbug/drivebase/lidar</frameName>
            </plugin>
            <always_on>true</always_on>
            <update_rate>100.0</update_rate>
        </sensor>
    </gazebo>
    <!--joint name="${ns}/lift2base" type="fixed">
      <parent link="${parent_link}"/>
      <child link="${ns}/base"/>
      <axis xyz="0 0 0" />
      <origin rpy="0 0 0" xyz="0 0 0"/>
    </joint>

    <link
      name="${ns}/base">
      <inertial>
      <origin xyz="0 0 0" rpy="0 0 0"/>
      <mass value=".0001"/>
      <inertia
        ixx="0.0001" ixy="0.0001" ixz="0.0001"
        iyy="0.0001" iyz="0.0001"
        izz="0.0001"/>
      </inertial>
    </link>-->
    <link name="stickbug/arm1/box">
        <inertial>
            <origin rpy="0 0 0" xyz="-0.0294836466854796 0.00650699178978326 0.044874078657663" />
            <mass value="1.25224595398726" />
            <inertia ixx="0.00206596064394956" ixy="-0.000334896166615364" ixz="0.000136948453654299" iyy="0.0035115970252851" iyz="-4.17254634185765E-05" izz="0.00431158338218049" />
        </inertial>
        <visual>
            <origin rpy="0 0 0" xyz="0 0 0" />
            <geometry>
                <mesh filename="package://poll_arm_left/meshes/box.STL" />
            </geometry>
            <material name="">
                <color rgba="0.792156862745098 0.819607843137255 0.933333333333333 1" />
            </material>
        </visual>
        <collision>
            <origin rpy="0 0 0" xyz="0 0 0" />
            <geometry>
                <mesh filename="package://poll_arm_left/meshes/box.STL" />
            </geometry>
        </collision>
    </link>
    <joint name="stickbug/arm1/slider" type="prismatic">
        <origin rpy="0 0 0" xyz="0 0 0" />
        <parent link="stickbug/drivebase/l_lift" />
        <child link="stickbug/arm1/box" />
        <axis xyz="0 0 1" />
        <limit effort="100" lower="0.01" upper="1.3" velocity=".5" />
        <dynamics damping="0.2" />
    </joint>
    <link name="stickbug/arm1/bicep">
        <inertial>
            <origin rpy="0 0 0" xyz="0.19577236492752 -0.0256170060224436 0.030251757517972" />
            <mass value="0.0881583450015477" />
            <inertia ixx="4.02190655717306E-05" ixy="9.41441514112841E-09" ixz="4.66388635592044E-08" iyy="2.35490419805005E-05" iyz="-9.36030697866667E-08" izz="3.32834464790013E-05" />
        </inertial>
        <visual>
            <origin rpy="0 0 0" xyz="0 0 0" />
            <geometry>
                <mesh filename="package://poll_arm_left/meshes/bicep.STL" />
            </geometry>
            <material name="">
                <color rgba="0.698039215686274 0.698039215686274 0.698039215686274 1" />
            </material>
        </visual>
        <collision>
            <origin rpy="0 0 0" xyz="0 0 0" />
            <geometry>
                <mesh filename="package://poll_arm_left/meshes/bicep.STL" />
            </geometry>
        </collision>
    </link>
    <joint name="stickbug/arm1/shoulder" type="revolute">
        <origin rpy="0 0 0.5236" xyz="0.10198 0.044401 0.019165" />
        <parent link="stickbug/arm1/box" />
        <child link="stickbug/arm1/bicep" />
        <axis xyz="0 0 1" />
        <limit effort="10" lower="-1.57" upper="1.57" velocity="1" />
        <dynamics damping="0.01" />
    </joint>
    <link name="stickbug/arm1/forearm">
        <inertial>
            <origin rpy="0 0 0" xyz="0.0765243373190795 0.00763087662935313 0.0278702986201432" />
            <mass value="0.0881583450015477" />
            <inertia ixx="4.02190655717306E-05" ixy="9.41441514112841E-09" ixz="4.66388635592044E-08" iyy="2.35490419805005E-05" iyz="-9.36030697866667E-08" izz="3.32834464790013E-05" />
        </inertial>
        <visual>
            <origin rpy="0 0 0" xyz="0 0 0" />
            <geometry>
                <mesh filename="package://poll_arm_left/meshes/forearm.STL" />
            </geometry>
            <material name="">
                <color rgba="0.698039215686274 0.698039215686274 0.698039215686274 1" />
            </material>
        </visual>
        <collision>
            <origin rpy="0 0 0" xyz="0 0 0" />
            <geometry>
                <mesh filename="package://poll_arm_left/meshes/forearm.STL" />
            </geometry>
        </collision>
    </link>
    <joint name="stickbug/arm1/elbow" type="revolute">
        <origin rpy="0 0 -1.5708" xyz="0.1959 -0.040686 0.0024841" />
        <parent link="stickbug/arm1/bicep" />
        <child link="stickbug/arm1/forearm" />
        <axis xyz="0 0 1" />
        <limit effort="10" lower="-1.57" upper="1.57" velocity="1" />
        <dynamics damping="0.01" />
    </joint>
    <link name="stickbug/arm1/w1_link">
        <inertial>
            <origin rpy="0 0 0" xyz="0.011999849295342 0.000549087822445393 0.0223834540031007" />
            <mass value="0.0565320862795783" />
            <inertia ixx="1.0226625085126E-05" ixy="-6.10475234166538E-10" ixz="7.97796107526984E-10" iyy="1.43894864274769E-05" iyz="3.44003507752819E-07" izz="1.4389503019841E-05" />
        </inertial>
        <visual>
            <origin rpy="0 0 0" xyz="0 0 0" />
            <geometry>
                <mesh filename="package://poll_arm_left/meshes/w1_link.STL" />
            </geometry>
            <material name="">
                <color rgba="0.792156862745098 0.819607843137255 0.933333333333333 1" />
            </material>
        </visual>
        <collision>
            <origin rpy="0 0 0" xyz="0 0 0" />
            <geometry>
                <mesh filename="package://poll_arm_left/meshes/w1_link.STL" />
            </geometry>
        </collision>
    </link>
    <joint name="stickbug/arm1/w1" type="revolute">
        <origin rpy="0 0 0" xyz="0.15435 0 0.0058612" />
        <parent link="stickbug/arm1/forearm" />
        <child link="stickbug/arm1/w1_link" />
        <axis xyz="0 0 1" />
        <limit effort="1" lower="-1.57" upper="1.57" velocity="1" />
        <dynamics damping="0.01" />
    </joint>
    <link name="stickbug/arm1/w2_link">
        <inertial>
            <origin rpy="0 0 0" xyz="0.0566451733011975 -0.00141725658574912 0.0284323416048119" />
            <mass value="0.153757182920479" />
            <inertia ixx="9.61201704567482E-05" ixy="-2.53181854057694E-06" ixz="1.28235405708061E-05" iyy="0.000113585627853035" iyz="-2.70973268265226E-06" izz="6.51970121574257E-05" />
        </inertial>
        <visual>
            <origin rpy="0 0 0" xyz="0 0 0" />
            <geometry>
                <mesh filename="package://poll_arm_left/meshes/w2_link.STL" />
            </geometry>
            <material name="">
                <color rgba="0.792156862745098 0.819607843137255 0.933333333333333 1" />
            </material>
        </visual>
        <collision>
            <origin rpy="0 0 0" xyz="0 0 0" />
            <geometry>
                <mesh filename="package://poll_arm_left/meshes/w2_link.STL" />
            </geometry>
        </collision>
    </link>
    <joint name="stickbug/arm1/w2" type="revolute">
        <origin rpy="-1.5708 0 0" xyz="0.024 -0.0222 0.021834" />
        <parent link="stickbug/arm1/w1_link" />
        <child link="stickbug/arm1/w2_link" />
        <axis xyz="0 0 1" />
        <limit effort="1" lower="-1.57" upper="1.57" velocity="1" />
        <dynamics damping="0.01" />
    </joint>
    <link name="stickbug/arm1/cam_link">
        <inertial>
            <origin rpy="0 0 0" xyz="-0.0113814657659481 -3.77656326211451E-08 -8.96828082673773E-05" />
            <mass value="0.039484046404376" />
            <inertia ixx="1.13008734896739E-05" ixy="-1.1840327216836E-12" ixz="-1.1184981555834E-08" iyy="7.34442345562825E-06" iyz="2.14724251253116E-11" izz="7.39890475454633E-06" />
        </inertial>
        <visual>
            <origin rpy="0 0 0" xyz="0 0 0" />
            <geometry>
                <mesh filename="package://poll_arm_left/meshes/cam_link.STL" />
            </geometry>
            <material name="">
                <color rgba="0.792156862745098 0.819607843137255 0.933333333333333 1" />
            </material>
        </visual>
        <collision>
            <origin rpy="0 0 0" xyz="0 0 0" />
            <geometry>
                <mesh filename="package://poll_arm_left/meshes/cam_link.STL" />
            </geometry>
        </collision>
    </link>
    <joint name="stickbug/arm1/cam_joint" type="fixed">
        <origin rpy="0 0.2618 0" xyz="0.063863 0 0.083432" />
        <parent link="stickbug/arm1/w2_link" />
        <child link="stickbug/arm1/cam_link" />
        <axis xyz="0 0 0" />
    </joint>
    <link name="stickbug/arm1/e1_link">
        <inertial>
            <origin rpy="0 0 0" xyz="0.00768377159854705 0.00530600599131281 -0.000730992899423188" />
            <mass value="0.00225996756513805" />
            <inertia ixx="1.30412723697187E-07" ixy="9.73218559749733E-08" ixz="2.16169394663049E-08" iyy="1.966205244536E-07" iyz="-1.2986245459416E-08" izz="3.15647081687985E-07" />
        </inertial>
        <visual>
            <origin rpy="0 0 0" xyz="0 0 0" />
            <geometry>
                <mesh filename="package://poll_arm_left/meshes/e1_link.STL" />
            </geometry>
            <material name="">
                <color rgba="0.792156862745098 0.819607843137255 0.933333333333333 1" />
            </material>
        </visual>
        <collision>
            <origin rpy="0 0 0" xyz="0 0 0" />
            <geometry>
                <mesh filename="package://poll_arm_left/meshes/e1_link.STL" />
            </geometry>
        </collision>
    </link>
    <joint name="stickbug/arm1/e1" type="revolute">
        <origin rpy="-1.0472 0 0" xyz="0.077 0.011263 0.0070007" />
        <parent link="stickbug/arm1/w2_link" />
        <child link="stickbug/arm1/e1_link" />
        <axis xyz="0 0 1" />
        <limit effort=".01" lower="-1.57" upper="1.57" velocity="1" />
        <dynamics damping="0.01" />
    </joint>
    <link name="stickbug/arm1/e2_link">
        <inertial>
            <origin rpy="0 0 0" xyz="0.00768377159939804 0.00530600599028475 -0.000730992897713945" />
            <mass value="0.00225996756505407" />
            <inertia ixx="1.30412723709295E-07" ixy="9.73218559904026E-08" ixz="2.16169394327849E-08" iyy="1.96620524444531E-07" iyz="-1.2986245443103E-08" izz="3.15647081713528E-07" />
        </inertial>
        <visual>
            <origin rpy="0 0 0" xyz="0 0 0" />
            <geometry>
                <mesh filename="package://poll_arm_left/meshes/e2_link.STL" />
            </geometry>
            <material name="">
                <color rgba="0.250980392156863 0.250980392156863 0.250980392156863 1" />
            </material>
        </visual>
        <collision>
            <origin rpy="0 0 0" xyz="0 0 0" />
            <geometry>
                <mesh filename="package://poll_arm_left/meshes/e2_link.STL" />
            </geometry>
        </collision>
    </link>
    <joint name="stickbug/arm1/e2" type="revolute">
        <origin rpy="1.0472 0 0" xyz="0.077 0.0074446 0.039404" />
        <parent link="stickbug/arm1/w2_link" />
        <child link="stickbug/arm1/e2_link" />
        <axis xyz="0 0 1" />
        <limit effort=".01" lower="-1.57" upper="1.57" velocity="1" />
        <dynamics damping="0.01" />
    </joint>
    <link name="stickbug/arm1/e3_link">
        <inertial>
            <origin rpy="0 0 0" xyz="0.00768377159880085 0.00530600599161343 -0.000730992902174321" />
            <mass value="0.00225996756527347" />
            <inertia ixx="1.30412723718879E-07" ixy="9.73218559573204E-08" ixz="2.16169395180174E-08" iyy="1.96620524429933E-07" iyz="-1.2986245490849E-08" izz="3.15647081641822E-07" />
        </inertial>
        <visual>
            <origin rpy="0 0 0" xyz="0 0 0" />
            <geometry>
                <mesh filename="package://poll_arm_left/meshes/e3_link.STL" />
            </geometry>
            <material name="">
                <color rgba="0.250980392156863 0.250980392156863 0.250980392156863 1" />
            </material>
        </visual>
        <collision>
            <origin rpy="0 0 0" xyz="0 0 0" />
            <geometry>
                <mesh filename="package://poll_arm_left/meshes/e3_link.STL" />
            </geometry>
        </collision>
    </link>
    <joint name="stickbug/arm1/e3" type="revolute">
        <origin rpy="3.1416 0 0" xyz="0.077 -0.018708 0.019895" />
        <parent link="stickbug/arm1/w2_link" />
        <child link="stickbug/arm1/e3_link" />
        <axis xyz="0 0 1" />
        <limit effort=".01" lower="-1.57" upper="1.57" velocity="1" />
        <dynamics damping="0.01" />
    </joint>
    <link name="stickbug/arm1/end_link">
        <inertial>
            <origin rpy="0 0 0" xyz="-0.00224236893916069 3.51872006532084E-08 -3.59307918973428E-08" />
            <mass value="0.00244973338644465" />
            <inertia ixx="2.1728168358708E-07" ixy="-1.95917302130553E-13" ixz="3.07605742817941E-13" iyy="1.14231479742372E-07" iyz="9.90134628383345E-13" izz="1.14231411420646E-07" />
        </inertial>
        <visual>
            <origin rpy="0 0 0" xyz="0 0 0" />
            <geometry>
                <mesh filename="package://poll_arm_left/meshes/end_link.STL" />
            </geometry>
            <material name="">
                <color rgba="0.792156862745098 0.819607843137255 0.933333333333333 1" />
            </material>
        </visual>
        <collision>
            <origin rpy="0 0 0" xyz="0 0 0" />
            <geometry>
                <mesh filename="package://poll_arm_left/meshes/end_link.STL" />
            </geometry>
        </collision>
    </link>
    <joint name="stickbug/arm1/end_joint" type="fixed">
        <origin rpy="1.5708 0 0" xyz="0.12293 0 0.0221" />
        <parent link="stickbug/arm1/w2_link" />
        <child link="stickbug/arm1/end_link" />
        <axis xyz="0 0 0" />
    </joint>
    <link name="stickbug/arm1/camera_frame" />
    <joint name="stickbug/arm1/cam_link2cam_frame" type="fixed">
        <parent link="stickbug/arm1/cam_link" />
        <child link="stickbug/arm1/camera_frame" />
        <origin rpy="-1.57 0.0 -1.57" xyz="0.0 0.0 0.0" />
    </joint>
    <transmission name="stickbug/arm1/trans_slider">
        <type>transmission_interface/SimpleTransmission</type>
        <joint name="stickbug/arm1/slider">
            <hardwareInterface>hardware_interface/EffortJointInterface</hardwareInterface>
        </joint>
        <actuator name="stickbug/arm1/slider_motor">
            <hardwareInterface>hardware_interface/EffortJointInterface</hardwareInterface>
            <mechanicalReduction>1</mechanicalReduction>
        </actuator>
    </transmission>
    <transmission name="stickbug/arm1/trans_shoulder">
        <type>transmission_interface/SimpleTransmission</type>
        <joint name="stickbug/arm1/shoulder">
            <hardwareInterface>hardware_interface/EffortJointInterface</hardwareInterface>
        </joint>
        <actuator name="stickbug/arm1/shoulder_motor">
            <hardwareInterface>hardware_interface/EffortJointInterface</hardwareInterface>
            <mechanicalReduction>1</mechanicalReduction>
        </actuator>
    </transmission>
    <transmission name="stickbug/arm1/trans_elbow">
        <type>transmission_interface/SimpleTransmission</type>
        <joint name="stickbug/arm1/elbow">
            <hardwareInterface>hardware_interface/EffortJointInterface</hardwareInterface>
        </joint>
        <actuator name="stickbug/arm1/elbow_motor">
            <hardwareInterface>hardware_interface/EffortJointInterface</hardwareInterface>
            <mechanicalReduction>1</mechanicalReduction>
        </actuator>
    </transmission>
    <transmission name="stickbug/arm1/trans_w1">
        <type>transmission_interface/SimpleTransmission</type>
        <joint name="stickbug/arm1/w1">
            <hardwareInterface>hardware_interface/EffortJointInterface</hardwareInterface>
        </joint>
        <actuator name="stickbug/arm1/w1_motor">
            <hardwareInterface>hardware_interface/EffortJointInterface</hardwareInterface>
            <mechanicalReduction>1</mechanicalReduction>
        </actuator>
    </transmission>
    <transmission name="stickbug/arm1/trans_w2">
        <type>transmission_interface/SimpleTransmission</type>
        <joint name="stickbug/arm1/w2">
            <hardwareInterface>hardware_interface/EffortJointInterface</hardwareInterface>
        </joint>
        <actuator name="stickbug/arm1/w2_motor">
            <hardwareInterface>hardware_interface/EffortJointInterface</hardwareInterface>
            <mechanicalReduction>1</mechanicalReduction>
        </actuator>
    </transmission>
    <transmission name="stickbug/arm1/trans_e1">
        <type>transmission_interface/SimpleTransmission</type>
        <joint name="stickbug/arm1/e1">
            <hardwareInterface>hardware_interface/EffortJointInterface</hardwareInterface>
        </joint>
        <actuator name="stickbug/arm1/e1_motor">
            <hardwareInterface>hardware_interface/EffortJointInterface</hardwareInterface>
            <mechanicalReduction>1</mechanicalReduction>
        </actuator>
    </transmission>
    <transmission name="stickbug/arm1/trans_e2">
        <type>transmission_interface/SimpleTransmission</type>
        <joint name="stickbug/arm1/e2">
            <hardwareInterface>hardware_interface/EffortJointInterface</hardwareInterface>
        </joint>
        <actuator name="stickbug/arm1/e2_motor">
            <hardwareInterface>hardware_interface/EffortJointInterface</hardwareInterface>
            <mechanicalReduction>1</mechanicalReduction>
        </actuator>
    </transmission>
    <transmission name="stickbug/arm1/trans_e3">
        <type>transmission_interface/SimpleTransmission</type>
        <joint name="stickbug/arm1/e3">
            <hardwareInterface>hardware_interface/EffortJointInterface</hardwareInterface>
        </joint>
        <actuator name="stickbug/arm1/e3_motor">
            <hardwareInterface>hardware_interface/EffortJointInterface</hardwareInterface>
            <mechanicalReduction>1</mechanicalReduction>
        </actuator>
    </transmission>
    <!--================================ right realsense plugin ================================-->
    <gazebo reference="stickbug/arm1/cam_link">
        <sensor name="stickbug/arm1/cam_link_camera" type="depth">
            <update_rate>20</update_rate>
            <camera>
                <horizontal_fov>1.047198</horizontal_fov>
                <image>
                    <width>640</width>
                    <height>480</height>
                    <format>R8G8B8</format>
                </image>
                <clip>
                    <near>0.05</near>
                    <far>3</far>
                </clip>
            </camera>
            <plugin filename="libgazebo_ros_openni_kinect.so" name="stickbug/arm1/cam_link_controller">
                <baseline>0.2</baseline>
                <alwaysOn>true</alwaysOn>
                <updateRate>1.0</updateRate>
                <cameraName>stickbug/arm1/cam_link</cameraName>
                <imageTopicName>color/image_raw</imageTopicName>
                <cameraInfoTopicName>color/camera_info</cameraInfoTopicName>
                <depthImageTopicName>depth/image_raw</depthImageTopicName>
                <depthImageInfoTopicName>depth/camera_info</depthImageInfoTopicName>
                <pointCloudTopicName>depth/points</pointCloudTopicName>
                <frameName>stickbug/arm1/camera_frame</frameName>
                <pointCloudCutoff>0.5</pointCloudCutoff>
                <pointCloudCutoffMax>3.0</pointCloudCutoffMax>
                <distortionK1>0.00000001</distortionK1>
                <distortionK2>0.00000001</distortionK2>
                <distortionK3>0.00000001</distortionK3>
                <distortionT1>0.00000001</distortionT1>
                <distortionT2>0.00000001</distortionT2>
                <CxPrime>0</CxPrime>
                <Cx>0</Cx>
                <Cy>0</Cy>
                <focalLength>0</focalLength>
                <hackBaseline>0</hackBaseline>
            </plugin>
        </sensor>
    </gazebo>
    <!--joint name="${ns}/lift2base" type="fixed">
      <parent link="${parent_link}"/>
      <child link="${ns}/base"/>
      <axis xyz="0 0 0" />
      <origin rpy="0 0 0" xyz="0 0 0"/>
    </joint>

    <link
      name="${ns}/base">
      <inertial>
      <origin xyz="0 0 0" rpy="0 0 0"/>
      <mass value=".0001"/>
      <inertia
        ixx="0.0001" ixy="0.0001" ixz="0.0001"
        iyy="0.0001" iyz="0.0001"
        izz="0.0001"/>
      </inertial>
    </link>-->
    <link name="stickbug/arm3/box">
        <inertial>
            <origin rpy="0 0 0" xyz="-0.0294836466854796 0.00650699178978326 0.044874078657663" />
            <mass value="1.25224595398726" />
            <inertia ixx="0.00206596064394956" ixy="-0.000334896166615364" ixz="0.000136948453654299" iyy="0.0035115970252851" iyz="-4.17254634185765E-05" izz="0.00431158338218049" />
        </inertial>
        <visual>
            <origin rpy="0 0 0" xyz="0 0 0" />
            <geometry>
                <mesh filename="package://poll_arm_left/meshes/box.STL" />
            </geometry>
            <material name="">
                <color rgba="0.792156862745098 0.819607843137255 0.933333333333333 1" />
            </material>
        </visual>
        <collision>
            <origin rpy="0 0 0" xyz="0 0 0" />
            <geometry>
                <mesh filename="package://poll_arm_left/meshes/box.STL" />
            </geometry>
        </collision>
    </link>
    <joint name="stickbug/arm3/slider" type="prismatic">
        <origin rpy="0 0 0" xyz="0 0 0" />
        <parent link="stickbug/drivebase/l_lift" />
        <child link="stickbug/arm3/box" />
        <axis xyz="0 0 1" />
        <limit effort="100" lower="0.01" upper="1.3" velocity=".5" />
        <dynamics damping="0.2" />
    </joint>
    <link name="stickbug/arm3/bicep">
        <inertial>
            <origin rpy="0 0 0" xyz="0.19577236492752 -0.0256170060224436 0.030251757517972" />
            <mass value="0.0881583450015477" />
            <inertia ixx="4.02190655717306E-05" ixy="9.41441514112841E-09" ixz="4.66388635592044E-08" iyy="2.35490419805005E-05" iyz="-9.36030697866667E-08" izz="3.32834464790013E-05" />
        </inertial>
        <visual>
            <origin rpy="0 0 0" xyz="0 0 0" />
            <geometry>
                <mesh filename="package://poll_arm_left/meshes/bicep.STL" />
            </geometry>
            <material name="">
                <color rgba="0.698039215686274 0.698039215686274 0.698039215686274 1" />
            </material>
        </visual>
        <collision>
            <origin rpy="0 0 0" xyz="0 0 0" />
            <geometry>
                <mesh filename="package://poll_arm_left/meshes/bicep.STL" />
            </geometry>
        </collision>
    </link>
    <joint name="stickbug/arm3/shoulder" type="revolute">
        <origin rpy="0 0 0.5236" xyz="0.10198 0.044401 0.019165" />
        <parent link="stickbug/arm3/box" />
        <child link="stickbug/arm3/bicep" />
        <axis xyz="0 0 1" />
        <limit effort="10" lower="-1.57" upper="1.57" velocity="1" />
        <dynamics damping="0.01" />
    </joint>
    <link name="stickbug/arm3/forearm">
        <inertial>
            <origin rpy="0 0 0" xyz="0.0765243373190795 0.00763087662935313 0.0278702986201432" />
            <mass value="0.0881583450015477" />
            <inertia ixx="4.02190655717306E-05" ixy="9.41441514112841E-09" ixz="4.66388635592044E-08" iyy="2.35490419805005E-05" iyz="-9.36030697866667E-08" izz="3.32834464790013E-05" />
        </inertial>
        <visual>
            <origin rpy="0 0 0" xyz="0 0 0" />
            <geometry>
                <mesh filename="package://poll_arm_left/meshes/forearm.STL" />
            </geometry>
            <material name="">
                <color rgba="0.698039215686274 0.698039215686274 0.698039215686274 1" />
            </material>
        </visual>
        <collision>
            <origin rpy="0 0 0" xyz="0 0 0" />
            <geometry>
                <mesh filename="package://poll_arm_left/meshes/forearm.STL" />
            </geometry>
        </collision>
    </link>
    <joint name="stickbug/arm3/elbow" type="revolute">
        <origin rpy="0 0 -1.5708" xyz="0.1959 -0.040686 0.0024841" />
        <parent link="stickbug/arm3/bicep" />
        <child link="stickbug/arm3/forearm" />
        <axis xyz="0 0 1" />
        <limit effort="10" lower="-1.57" upper="1.57" velocity="1" />
        <dynamics damping="0.01" />
    </joint>
    <link name="stickbug/arm3/w1_link">
        <inertial>
            <origin rpy="0 0 0" xyz="0.011999849295342 0.000549087822445393 0.0223834540031007" />
            <mass value="0.0565320862795783" />
            <inertia ixx="1.0226625085126E-05" ixy="-6.10475234166538E-10" ixz="7.97796107526984E-10" iyy="1.43894864274769E-05" iyz="3.44003507752819E-07" izz="1.4389503019841E-05" />
        </inertial>
        <visual>
            <origin rpy="0 0 0" xyz="0 0 0" />
            <geometry>
                <mesh filename="package://poll_arm_left/meshes/w1_link.STL" />
            </geometry>
            <material name="">
                <color rgba="0.792156862745098 0.819607843137255 0.933333333333333 1" />
            </material>
        </visual>
        <collision>
            <origin rpy="0 0 0" xyz="0 0 0" />
            <geometry>
                <mesh filename="package://poll_arm_left/meshes/w1_link.STL" />
            </geometry>
        </collision>
    </link>
    <joint name="stickbug/arm3/w1" type="revolute">
        <origin rpy="0 0 0" xyz="0.15435 0 0.0058612" />
        <parent link="stickbug/arm3/forearm" />
        <child link="stickbug/arm3/w1_link" />
        <axis xyz="0 0 1" />
        <limit effort="1" lower="-1.57" upper="1.57" velocity="1" />
        <dynamics damping="0.01" />
    </joint>
    <link name="stickbug/arm3/w2_link">
        <inertial>
            <origin rpy="0 0 0" xyz="0.0566451733011975 -0.00141725658574912 0.0284323416048119" />
            <mass value="0.153757182920479" />
            <inertia ixx="9.61201704567482E-05" ixy="-2.53181854057694E-06" ixz="1.28235405708061E-05" iyy="0.000113585627853035" iyz="-2.70973268265226E-06" izz="6.51970121574257E-05" />
        </inertial>
        <visual>
            <origin rpy="0 0 0" xyz="0 0 0" />
            <geometry>
                <mesh filename="package://poll_arm_left/meshes/w2_link.STL" />
            </geometry>
            <material name="">
                <color rgba="0.792156862745098 0.819607843137255 0.933333333333333 1" />
            </material>
        </visual>
        <collision>
            <origin rpy="0 0 0" xyz="0 0 0" />
            <geometry>
                <mesh filename="package://poll_arm_left/meshes/w2_link.STL" />
            </geometry>
        </collision>
    </link>
    <joint name="stickbug/arm3/w2" type="revolute">
        <origin rpy="-1.5708 0 0" xyz="0.024 -0.0222 0.021834" />
        <parent link="stickbug/arm3/w1_link" />
        <child link="stickbug/arm3/w2_link" />
        <axis xyz="0 0 1" />
        <limit effort="1" lower="-1.57" upper="1.57" velocity="1" />
        <dynamics damping="0.01" />
    </joint>
    <link name="stickbug/arm3/cam_link">
        <inertial>
            <origin rpy="0 0 0" xyz="-0.0113814657659481 -3.77656326211451E-08 -8.96828082673773E-05" />
            <mass value="0.039484046404376" />
            <inertia ixx="1.13008734896739E-05" ixy="-1.1840327216836E-12" ixz="-1.1184981555834E-08" iyy="7.34442345562825E-06" iyz="2.14724251253116E-11" izz="7.39890475454633E-06" />
        </inertial>
        <visual>
            <origin rpy="0 0 0" xyz="0 0 0" />
            <geometry>
                <mesh filename="package://poll_arm_left/meshes/cam_link.STL" />
            </geometry>
            <material name="">
                <color rgba="0.792156862745098 0.819607843137255 0.933333333333333 1" />
            </material>
        </visual>
        <collision>
            <origin rpy="0 0 0" xyz="0 0 0" />
            <geometry>
                <mesh filename="package://poll_arm_left/meshes/cam_link.STL" />
            </geometry>
        </collision>
    </link>
    <joint name="stickbug/arm3/cam_joint" type="fixed">
        <origin rpy="0 0.2618 0" xyz="0.063863 0 0.083432" />
        <parent link="stickbug/arm3/w2_link" />
        <child link="stickbug/arm3/cam_link" />
        <axis xyz="0 0 0" />
    </joint>
    <link name="stickbug/arm3/e1_link">
        <inertial>
            <origin rpy="0 0 0" xyz="0.00768377159854705 0.00530600599131281 -0.000730992899423188" />
            <mass value="0.00225996756513805" />
            <inertia ixx="1.30412723697187E-07" ixy="9.73218559749733E-08" ixz="2.16169394663049E-08" iyy="1.966205244536E-07" iyz="-1.2986245459416E-08" izz="3.15647081687985E-07" />
        </inertial>
        <visual>
            <origin rpy="0 0 0" xyz="0 0 0" />
            <geometry>
                <mesh filename="package://poll_arm_left/meshes/e1_link.STL" />
            </geometry>
            <material name="">
                <color rgba="0.792156862745098 0.819607843137255 0.933333333333333 1" />
            </material>
        </visual>
        <collision>
            <origin rpy="0 0 0" xyz="0 0 0" />
            <geometry>
                <mesh filename="package://poll_arm_left/meshes/e1_link.STL" />
            </geometry>
        </collision>
    </link>
    <joint name="stickbug/arm3/e1" type="revolute">
        <origin rpy="-1.0472 0 0" xyz="0.077 0.011263 0.0070007" />
        <parent link="stickbug/arm3/w2_link" />
        <child link="stickbug/arm3/e1_link" />
        <axis xyz="0 0 1" />
        <limit effort=".01" lower="-1.57" upper="1.57" velocity="1" />
        <dynamics damping="0.01" />
    </joint>
    <link name="stickbug/arm3/e2_link">
        <inertial>
            <origin rpy="0 0 0" xyz="0.00768377159939804 0.00530600599028475 -0.000730992897713945" />
            <mass value="0.00225996756505407" />
            <inertia ixx="1.30412723709295E-07" ixy="9.73218559904026E-08" ixz="2.16169394327849E-08" iyy="1.96620524444531E-07" iyz="-1.2986245443103E-08" izz="3.15647081713528E-07" />
        </inertial>
        <visual>
            <origin rpy="0 0 0" xyz="0 0 0" />
            <geometry>
                <mesh filename="package://poll_arm_left/meshes/e2_link.STL" />
            </geometry>
            <material name="">
                <color rgba="0.250980392156863 0.250980392156863 0.250980392156863 1" />
            </material>
        </visual>
        <collision>
            <origin rpy="0 0 0" xyz="0 0 0" />
            <geometry>
                <mesh filename="package://poll_arm_left/meshes/e2_link.STL" />
            </geometry>
        </collision>
    </link>
    <joint name="stickbug/arm3/e2" type="revolute">
        <origin rpy="1.0472 0 0" xyz="0.077 0.0074446 0.039404" />
        <parent link="stickbug/arm3/w2_link" />
        <child link="stickbug/arm3/e2_link" />
        <axis xyz="0 0 1" />
        <limit effort=".01" lower="-1.57" upper="1.57" velocity="1" />
        <dynamics damping="0.01" />
    </joint>
    <link name="stickbug/arm3/e3_link">
        <inertial>
            <origin rpy="0 0 0" xyz="0.00768377159880085 0.00530600599161343 -0.000730992902174321" />
            <mass value="0.00225996756527347" />
            <inertia ixx="1.30412723718879E-07" ixy="9.73218559573204E-08" ixz="2.16169395180174E-08" iyy="1.96620524429933E-07" iyz="-1.2986245490849E-08" izz="3.15647081641822E-07" />
        </inertial>
        <visual>
            <origin rpy="0 0 0" xyz="0 0 0" />
            <geometry>
                <mesh filename="package://poll_arm_left/meshes/e3_link.STL" />
            </geometry>
            <material name="">
                <color rgba="0.250980392156863 0.250980392156863 0.250980392156863 1" />
            </material>
        </visual>
        <collision>
            <origin rpy="0 0 0" xyz="0 0 0" />
            <geometry>
                <mesh filename="package://poll_arm_left/meshes/e3_link.STL" />
            </geometry>
        </collision>
    </link>
    <joint name="stickbug/arm3/e3" type="revolute">
        <origin rpy="3.1416 0 0" xyz="0.077 -0.018708 0.019895" />
        <parent link="stickbug/arm3/w2_link" />
        <child link="stickbug/arm3/e3_link" />
        <axis xyz="0 0 1" />
        <limit effort=".01" lower="-1.57" upper="1.57" velocity="1" />
        <dynamics damping="0.01" />
    </joint>
    <link name="stickbug/arm3/end_link">
        <inertial>
            <origin rpy="0 0 0" xyz="-0.00224236893916069 3.51872006532084E-08 -3.59307918973428E-08" />
            <mass value="0.00244973338644465" />
            <inertia ixx="2.1728168358708E-07" ixy="-1.95917302130553E-13" ixz="3.07605742817941E-13" iyy="1.14231479742372E-07" iyz="9.90134628383345E-13" izz="1.14231411420646E-07" />
        </inertial>
        <visual>
            <origin rpy="0 0 0" xyz="0 0 0" />
            <geometry>
                <mesh filename="package://poll_arm_left/meshes/end_link.STL" />
            </geometry>
            <material name="">
                <color rgba="0.792156862745098 0.819607843137255 0.933333333333333 1" />
            </material>
        </visual>
        <collision>
            <origin rpy="0 0 0" xyz="0 0 0" />
            <geometry>
                <mesh filename="package://poll_arm_left/meshes/end_link.STL" />
            </geometry>
        </collision>
    </link>
    <joint name="stickbug/arm3/end_joint" type="fixed">
        <origin rpy="1.5708 0 0" xyz="0.12293 0 0.0221" />
        <parent link="stickbug/arm3/w2_link" />
        <child link="stickbug/arm3/end_link" />
        <axis xyz="0 0 0" />
    </joint>
    <link name="stickbug/arm3/camera_frame" />
    <joint name="stickbug/arm3/cam_link2cam_frame" type="fixed">
        <parent link="stickbug/arm3/cam_link" />
        <child link="stickbug/arm3/camera_frame" />
        <origin rpy="-1.57 0.0 -1.57" xyz="0.0 0.0 0.0" />
    </joint>
    <transmission name="stickbug/arm3/trans_slider">
        <type>transmission_interface/SimpleTransmission</type>
        <joint name="stickbug/arm3/slider">
            <hardwareInterface>hardware_interface/EffortJointInterface</hardwareInterface>
        </joint>
        <actuator name="stickbug/arm3/slider_motor">
            <hardwareInterface>hardware_interface/EffortJointInterface</hardwareInterface>
            <mechanicalReduction>1</mechanicalReduction>
        </actuator>
    </transmission>
    <transmission name="stickbug/arm3/trans_shoulder">
        <type>transmission_interface/SimpleTransmission</type>
        <joint name="stickbug/arm3/shoulder">
            <hardwareInterface>hardware_interface/EffortJointInterface</hardwareInterface>
        </joint>
        <actuator name="stickbug/arm3/shoulder_motor">
            <hardwareInterface>hardware_interface/EffortJointInterface</hardwareInterface>
            <mechanicalReduction>1</mechanicalReduction>
        </actuator>
    </transmission>
    <transmission name="stickbug/arm3/trans_elbow">
        <type>transmission_interface/SimpleTransmission</type>
        <joint name="stickbug/arm3/elbow">
            <hardwareInterface>hardware_interface/EffortJointInterface</hardwareInterface>
        </joint>
        <actuator name="stickbug/arm3/elbow_motor">
            <hardwareInterface>hardware_interface/EffortJointInterface</hardwareInterface>
            <mechanicalReduction>1</mechanicalReduction>
        </actuator>
    </transmission>
    <transmission name="stickbug/arm3/trans_w1">
        <type>transmission_interface/SimpleTransmission</type>
        <joint name="stickbug/arm3/w1">
            <hardwareInterface>hardware_interface/EffortJointInterface</hardwareInterface>
        </joint>
        <actuator name="stickbug/arm3/w1_motor">
            <hardwareInterface>hardware_interface/EffortJointInterface</hardwareInterface>
            <mechanicalReduction>1</mechanicalReduction>
        </actuator>
    </transmission>
    <transmission name="stickbug/arm3/trans_w2">
        <type>transmission_interface/SimpleTransmission</type>
        <joint name="stickbug/arm3/w2">
            <hardwareInterface>hardware_interface/EffortJointInterface</hardwareInterface>
        </joint>
        <actuator name="stickbug/arm3/w2_motor">
            <hardwareInterface>hardware_interface/EffortJointInterface</hardwareInterface>
            <mechanicalReduction>1</mechanicalReduction>
        </actuator>
    </transmission>
    <transmission name="stickbug/arm3/trans_e1">
        <type>transmission_interface/SimpleTransmission</type>
        <joint name="stickbug/arm3/e1">
            <hardwareInterface>hardware_interface/EffortJointInterface</hardwareInterface>
        </joint>
        <actuator name="stickbug/arm3/e1_motor">
            <hardwareInterface>hardware_interface/EffortJointInterface</hardwareInterface>
            <mechanicalReduction>1</mechanicalReduction>
        </actuator>
    </transmission>
    <transmission name="stickbug/arm3/trans_e2">
        <type>transmission_interface/SimpleTransmission</type>
        <joint name="stickbug/arm3/e2">
            <hardwareInterface>hardware_interface/EffortJointInterface</hardwareInterface>
        </joint>
        <actuator name="stickbug/arm3/e2_motor">
            <hardwareInterface>hardware_interface/EffortJointInterface</hardwareInterface>
            <mechanicalReduction>1</mechanicalReduction>
        </actuator>
    </transmission>
    <transmission name="stickbug/arm3/trans_e3">
        <type>transmission_interface/SimpleTransmission</type>
        <joint name="stickbug/arm3/e3">
            <hardwareInterface>hardware_interface/EffortJointInterface</hardwareInterface>
        </joint>
        <actuator name="stickbug/arm3/e3_motor">
            <hardwareInterface>hardware_interface/EffortJointInterface</hardwareInterface>
            <mechanicalReduction>1</mechanicalReduction>
        </actuator>
    </transmission>
    <!--================================ right realsense plugin ================================-->
    <gazebo reference="stickbug/arm3/cam_link">
        <sensor name="stickbug/arm3/cam_link_camera" type="depth">
            <update_rate>20</update_rate>
            <camera>
                <horizontal_fov>1.047198</horizontal_fov>
                <image>
                    <width>640</width>
                    <height>480</height>
                    <format>R8G8B8</format>
                </image>
                <clip>
                    <near>0.05</near>
                    <far>3</far>
                </clip>
            </camera>
            <plugin filename="libgazebo_ros_openni_kinect.so" name="stickbug/arm3/cam_link_controller">
                <baseline>0.2</baseline>
                <alwaysOn>true</alwaysOn>
                <updateRate>1.0</updateRate>
                <cameraName>stickbug/arm3/cam_link</cameraName>
                <imageTopicName>color/image_raw</imageTopicName>
                <cameraInfoTopicName>color/camera_info</cameraInfoTopicName>
                <depthImageTopicName>depth/image_raw</depthImageTopicName>
                <depthImageInfoTopicName>depth/camera_info</depthImageInfoTopicName>
                <pointCloudTopicName>depth/points</pointCloudTopicName>
                <frameName>stickbug/arm3/camera_frame</frameName>
                <pointCloudCutoff>0.5</pointCloudCutoff>
                <pointCloudCutoffMax>3.0</pointCloudCutoffMax>
                <distortionK1>0.00000001</distortionK1>
                <distortionK2>0.00000001</distortionK2>
                <distortionK3>0.00000001</distortionK3>
                <distortionT1>0.00000001</distortionT1>
                <distortionT2>0.00000001</distortionT2>
                <CxPrime>0</CxPrime>
                <Cx>0</Cx>
                <Cy>0</Cy>
                <focalLength>0</focalLength>
                <hackBaseline>0</hackBaseline>
            </plugin>
        </sensor>
    </gazebo>
    <!--joint name="${ns}/lift2base" type="fixed">
      <parent link="${parent_link}"/>
      <child link="${ns}/base"/>
      <axis xyz="0 0 0" />
      <origin rpy="0 0 0" xyz="0 0 0"/>
    </joint>

    <link
      name="${ns}/base">
      <inertial>
      <origin xyz="0 0 0" rpy="0 0 0"/>
      <mass value=".0001"/>
      <inertia
        ixx="0.0001" ixy="0.0001" ixz="0.0001"
        iyy="0.0001" iyz="0.0001"
        izz="0.0001"/>
      </inertial>
    </link>-->
    <link name="stickbug/arm5/box">
        <inertial>
            <origin rpy="0 0 0" xyz="-0.0294836466854796 0.00650699178978326 0.044874078657663" />
            <mass value="1.25224595398726" />
            <inertia ixx="0.00206596064394956" ixy="-0.000334896166615364" ixz="0.000136948453654299" iyy="0.0035115970252851" iyz="-4.17254634185765E-05" izz="0.00431158338218049" />
        </inertial>
        <visual>
            <origin rpy="0 0 0" xyz="0 0 0" />
            <geometry>
                <mesh filename="package://poll_arm_left/meshes/box.STL" />
            </geometry>
            <material name="">
                <color rgba="0.792156862745098 0.819607843137255 0.933333333333333 1" />
            </material>
        </visual>
        <collision>
            <origin rpy="0 0 0" xyz="0 0 0" />
            <geometry>
                <mesh filename="package://poll_arm_left/meshes/box.STL" />
            </geometry>
        </collision>
    </link>
    <joint name="stickbug/arm5/slider" type="prismatic">
        <origin rpy="0 0 0" xyz="0 0 0" />
        <parent link="stickbug/drivebase/l_lift" />
        <child link="stickbug/arm5/box" />
        <axis xyz="0 0 1" />
        <limit effort="100" lower="0.01" upper="1.3" velocity=".5" />
        <dynamics damping="0.2" />
    </joint>
    <link name="stickbug/arm5/bicep">
        <inertial>
            <origin rpy="0 0 0" xyz="0.19577236492752 -0.0256170060224436 0.030251757517972" />
            <mass value="0.0881583450015477" />
            <inertia ixx="4.02190655717306E-05" ixy="9.41441514112841E-09" ixz="4.66388635592044E-08" iyy="2.35490419805005E-05" iyz="-9.36030697866667E-08" izz="3.32834464790013E-05" />
        </inertial>
        <visual>
            <origin rpy="0 0 0" xyz="0 0 0" />
            <geometry>
                <mesh filename="package://poll_arm_left/meshes/bicep.STL" />
            </geometry>
            <material name="">
                <color rgba="0.698039215686274 0.698039215686274 0.698039215686274 1" />
            </material>
        </visual>
        <collision>
            <origin rpy="0 0 0" xyz="0 0 0" />
            <geometry>
                <mesh filename="package://poll_arm_left/meshes/bicep.STL" />
            </geometry>
        </collision>
    </link>
    <joint name="stickbug/arm5/shoulder" type="revolute">
        <origin rpy="0 0 0.5236" xyz="0.10198 0.044401 0.019165" />
        <parent link="stickbug/arm5/box" />
        <child link="stickbug/arm5/bicep" />
        <axis xyz="0 0 1" />
        <limit effort="10" lower="-1.57" upper="1.57" velocity="1" />
        <dynamics damping="0.01" />
    </joint>
    <link name="stickbug/arm5/forearm">
        <inertial>
            <origin rpy="0 0 0" xyz="0.0765243373190795 0.00763087662935313 0.0278702986201432" />
            <mass value="0.0881583450015477" />
            <inertia ixx="4.02190655717306E-05" ixy="9.41441514112841E-09" ixz="4.66388635592044E-08" iyy="2.35490419805005E-05" iyz="-9.36030697866667E-08" izz="3.32834464790013E-05" />
        </inertial>
        <visual>
            <origin rpy="0 0 0" xyz="0 0 0" />
            <geometry>
                <mesh filename="package://poll_arm_left/meshes/forearm.STL" />
            </geometry>
            <material name="">
                <color rgba="0.698039215686274 0.698039215686274 0.698039215686274 1" />
            </material>
        </visual>
        <collision>
            <origin rpy="0 0 0" xyz="0 0 0" />
            <geometry>
                <mesh filename="package://poll_arm_left/meshes/forearm.STL" />
            </geometry>
        </collision>
    </link>
    <joint name="stickbug/arm5/elbow" type="revolute">
        <origin rpy="0 0 -1.5708" xyz="0.1959 -0.040686 0.0024841" />
        <parent link="stickbug/arm5/bicep" />
        <child link="stickbug/arm5/forearm" />
        <axis xyz="0 0 1" />
        <limit effort="10" lower="-1.57" upper="1.57" velocity="1" />
        <dynamics damping="0.01" />
    </joint>
    <link name="stickbug/arm5/w1_link">
        <inertial>
            <origin rpy="0 0 0" xyz="0.011999849295342 0.000549087822445393 0.0223834540031007" />
            <mass value="0.0565320862795783" />
            <inertia ixx="1.0226625085126E-05" ixy="-6.10475234166538E-10" ixz="7.97796107526984E-10" iyy="1.43894864274769E-05" iyz="3.44003507752819E-07" izz="1.4389503019841E-05" />
        </inertial>
        <visual>
            <origin rpy="0 0 0" xyz="0 0 0" />
            <geometry>
                <mesh filename="package://poll_arm_left/meshes/w1_link.STL" />
            </geometry>
            <material name="">
                <color rgba="0.792156862745098 0.819607843137255 0.933333333333333 1" />
            </material>
        </visual>
        <collision>
            <origin rpy="0 0 0" xyz="0 0 0" />
            <geometry>
                <mesh filename="package://poll_arm_left/meshes/w1_link.STL" />
            </geometry>
        </collision>
    </link>
    <joint name="stickbug/arm5/w1" type="revolute">
        <origin rpy="0 0 0" xyz="0.15435 0 0.0058612" />
        <parent link="stickbug/arm5/forearm" />
        <child link="stickbug/arm5/w1_link" />
        <axis xyz="0 0 1" />
        <limit effort="1" lower="-1.57" upper="1.57" velocity="1" />
        <dynamics damping="0.01" />
    </joint>
    <link name="stickbug/arm5/w2_link">
        <inertial>
            <origin rpy="0 0 0" xyz="0.0566451733011975 -0.00141725658574912 0.0284323416048119" />
            <mass value="0.153757182920479" />
            <inertia ixx="9.61201704567482E-05" ixy="-2.53181854057694E-06" ixz="1.28235405708061E-05" iyy="0.000113585627853035" iyz="-2.70973268265226E-06" izz="6.51970121574257E-05" />
        </inertial>
        <visual>
            <origin rpy="0 0 0" xyz="0 0 0" />
            <geometry>
                <mesh filename="package://poll_arm_left/meshes/w2_link.STL" />
            </geometry>
            <material name="">
                <color rgba="0.792156862745098 0.819607843137255 0.933333333333333 1" />
            </material>
        </visual>
        <collision>
            <origin rpy="0 0 0" xyz="0 0 0" />
            <geometry>
                <mesh filename="package://poll_arm_left/meshes/w2_link.STL" />
            </geometry>
        </collision>
    </link>
    <joint name="stickbug/arm5/w2" type="revolute">
        <origin rpy="-1.5708 0 0" xyz="0.024 -0.0222 0.021834" />
        <parent link="stickbug/arm5/w1_link" />
        <child link="stickbug/arm5/w2_link" />
        <axis xyz="0 0 1" />
        <limit effort="1" lower="-1.57" upper="1.57" velocity="1" />
        <dynamics damping="0.01" />
    </joint>
    <link name="stickbug/arm5/cam_link">
        <inertial>
            <origin rpy="0 0 0" xyz="-0.0113814657659481 -3.77656326211451E-08 -8.96828082673773E-05" />
            <mass value="0.039484046404376" />
            <inertia ixx="1.13008734896739E-05" ixy="-1.1840327216836E-12" ixz="-1.1184981555834E-08" iyy="7.34442345562825E-06" iyz="2.14724251253116E-11" izz="7.39890475454633E-06" />
        </inertial>
        <visual>
            <origin rpy="0 0 0" xyz="0 0 0" />
            <geometry>
                <mesh filename="package://poll_arm_left/meshes/cam_link.STL" />
            </geometry>
            <material name="">
                <color rgba="0.792156862745098 0.819607843137255 0.933333333333333 1" />
            </material>
        </visual>
        <collision>
            <origin rpy="0 0 0" xyz="0 0 0" />
            <geometry>
                <mesh filename="package://poll_arm_left/meshes/cam_link.STL" />
            </geometry>
        </collision>
    </link>
    <joint name="stickbug/arm5/cam_joint" type="fixed">
        <origin rpy="0 0.2618 0" xyz="0.063863 0 0.083432" />
        <parent link="stickbug/arm5/w2_link" />
        <child link="stickbug/arm5/cam_link" />
        <axis xyz="0 0 0" />
    </joint>
    <link name="stickbug/arm5/e1_link">
        <inertial>
            <origin rpy="0 0 0" xyz="0.00768377159854705 0.00530600599131281 -0.000730992899423188" />
            <mass value="0.00225996756513805" />
            <inertia ixx="1.30412723697187E-07" ixy="9.73218559749733E-08" ixz="2.16169394663049E-08" iyy="1.966205244536E-07" iyz="-1.2986245459416E-08" izz="3.15647081687985E-07" />
        </inertial>
        <visual>
            <origin rpy="0 0 0" xyz="0 0 0" />
            <geometry>
                <mesh filename="package://poll_arm_left/meshes/e1_link.STL" />
            </geometry>
            <material name="">
                <color rgba="0.792156862745098 0.819607843137255 0.933333333333333 1" />
            </material>
        </visual>
        <collision>
            <origin rpy="0 0 0" xyz="0 0 0" />
            <geometry>
                <mesh filename="package://poll_arm_left/meshes/e1_link.STL" />
            </geometry>
        </collision>
    </link>
    <joint name="stickbug/arm5/e1" type="revolute">
        <origin rpy="-1.0472 0 0" xyz="0.077 0.011263 0.0070007" />
        <parent link="stickbug/arm5/w2_link" />
        <child link="stickbug/arm5/e1_link" />
        <axis xyz="0 0 1" />
        <limit effort=".01" lower="-1.57" upper="1.57" velocity="1" />
        <dynamics damping="0.01" />
    </joint>
    <link name="stickbug/arm5/e2_link">
        <inertial>
            <origin rpy="0 0 0" xyz="0.00768377159939804 0.00530600599028475 -0.000730992897713945" />
            <mass value="0.00225996756505407" />
            <inertia ixx="1.30412723709295E-07" ixy="9.73218559904026E-08" ixz="2.16169394327849E-08" iyy="1.96620524444531E-07" iyz="-1.2986245443103E-08" izz="3.15647081713528E-07" />
        </inertial>
        <visual>
            <origin rpy="0 0 0" xyz="0 0 0" />
            <geometry>
                <mesh filename="package://poll_arm_left/meshes/e2_link.STL" />
            </geometry>
            <material name="">
                <color rgba="0.250980392156863 0.250980392156863 0.250980392156863 1" />
            </material>
        </visual>
        <collision>
            <origin rpy="0 0 0" xyz="0 0 0" />
            <geometry>
                <mesh filename="package://poll_arm_left/meshes/e2_link.STL" />
            </geometry>
        </collision>
    </link>
    <joint name="stickbug/arm5/e2" type="revolute">
        <origin rpy="1.0472 0 0" xyz="0.077 0.0074446 0.039404" />
        <parent link="stickbug/arm5/w2_link" />
        <child link="stickbug/arm5/e2_link" />
        <axis xyz="0 0 1" />
        <limit effort=".01" lower="-1.57" upper="1.57" velocity="1" />
        <dynamics damping="0.01" />
    </joint>
    <link name="stickbug/arm5/e3_link">
        <inertial>
            <origin rpy="0 0 0" xyz="0.00768377159880085 0.00530600599161343 -0.000730992902174321" />
            <mass value="0.00225996756527347" />
            <inertia ixx="1.30412723718879E-07" ixy="9.73218559573204E-08" ixz="2.16169395180174E-08" iyy="1.96620524429933E-07" iyz="-1.2986245490849E-08" izz="3.15647081641822E-07" />
        </inertial>
        <visual>
            <origin rpy="0 0 0" xyz="0 0 0" />
            <geometry>
                <mesh filename="package://poll_arm_left/meshes/e3_link.STL" />
            </geometry>
            <material name="">
                <color rgba="0.250980392156863 0.250980392156863 0.250980392156863 1" />
            </material>
        </visual>
        <collision>
            <origin rpy="0 0 0" xyz="0 0 0" />
            <geometry>
                <mesh filename="package://poll_arm_left/meshes/e3_link.STL" />
            </geometry>
        </collision>
    </link>
    <joint name="stickbug/arm5/e3" type="revolute">
        <origin rpy="3.1416 0 0" xyz="0.077 -0.018708 0.019895" />
        <parent link="stickbug/arm5/w2_link" />
        <child link="stickbug/arm5/e3_link" />
        <axis xyz="0 0 1" />
        <limit effort=".01" lower="-1.57" upper="1.57" velocity="1" />
        <dynamics damping="0.01" />
    </joint>
    <link name="stickbug/arm5/end_link">
        <inertial>
            <origin rpy="0 0 0" xyz="-0.00224236893916069 3.51872006532084E-08 -3.59307918973428E-08" />
            <mass value="0.00244973338644465" />
            <inertia ixx="2.1728168358708E-07" ixy="-1.95917302130553E-13" ixz="3.07605742817941E-13" iyy="1.14231479742372E-07" iyz="9.90134628383345E-13" izz="1.14231411420646E-07" />
        </inertial>
        <visual>
            <origin rpy="0 0 0" xyz="0 0 0" />
            <geometry>
                <mesh filename="package://poll_arm_left/meshes/end_link.STL" />
            </geometry>
            <material name="">
                <color rgba="0.792156862745098 0.819607843137255 0.933333333333333 1" />
            </material>
        </visual>
        <collision>
            <origin rpy="0 0 0" xyz="0 0 0" />
            <geometry>
                <mesh filename="package://poll_arm_left/meshes/end_link.STL" />
            </geometry>
        </collision>
    </link>
    <joint name="stickbug/arm5/end_joint" type="fixed">
        <origin rpy="1.5708 0 0" xyz="0.12293 0 0.0221" />
        <parent link="stickbug/arm5/w2_link" />
        <child link="stickbug/arm5/end_link" />
        <axis xyz="0 0 0" />
    </joint>
    <link name="stickbug/arm5/camera_frame" />
    <joint name="stickbug/arm5/cam_link2cam_frame" type="fixed">
        <parent link="stickbug/arm5/cam_link" />
        <child link="stickbug/arm5/camera_frame" />
        <origin rpy="-1.57 0.0 -1.57" xyz="0.0 0.0 0.0" />
    </joint>
    <transmission name="stickbug/arm5/trans_slider">
        <type>transmission_interface/SimpleTransmission</type>
        <joint name="stickbug/arm5/slider">
            <hardwareInterface>hardware_interface/EffortJointInterface</hardwareInterface>
        </joint>
        <actuator name="stickbug/arm5/slider_motor">
            <hardwareInterface>hardware_interface/EffortJointInterface</hardwareInterface>
            <mechanicalReduction>1</mechanicalReduction>
        </actuator>
    </transmission>
    <transmission name="stickbug/arm5/trans_shoulder">
        <type>transmission_interface/SimpleTransmission</type>
        <joint name="stickbug/arm5/shoulder">
            <hardwareInterface>hardware_interface/EffortJointInterface</hardwareInterface>
        </joint>
        <actuator name="stickbug/arm5/shoulder_motor">
            <hardwareInterface>hardware_interface/EffortJointInterface</hardwareInterface>
            <mechanicalReduction>1</mechanicalReduction>
        </actuator>
    </transmission>
    <transmission name="stickbug/arm5/trans_elbow">
        <type>transmission_interface/SimpleTransmission</type>
        <joint name="stickbug/arm5/elbow">
            <hardwareInterface>hardware_interface/EffortJointInterface</hardwareInterface>
        </joint>
        <actuator name="stickbug/arm5/elbow_motor">
            <hardwareInterface>hardware_interface/EffortJointInterface</hardwareInterface>
            <mechanicalReduction>1</mechanicalReduction>
        </actuator>
    </transmission>
    <transmission name="stickbug/arm5/trans_w1">
        <type>transmission_interface/SimpleTransmission</type>
        <joint name="stickbug/arm5/w1">
            <hardwareInterface>hardware_interface/EffortJointInterface</hardwareInterface>
        </joint>
        <actuator name="stickbug/arm5/w1_motor">
            <hardwareInterface>hardware_interface/EffortJointInterface</hardwareInterface>
            <mechanicalReduction>1</mechanicalReduction>
        </actuator>
    </transmission>
    <transmission name="stickbug/arm5/trans_w2">
        <type>transmission_interface/SimpleTransmission</type>
        <joint name="stickbug/arm5/w2">
            <hardwareInterface>hardware_interface/EffortJointInterface</hardwareInterface>
        </joint>
        <actuator name="stickbug/arm5/w2_motor">
            <hardwareInterface>hardware_interface/EffortJointInterface</hardwareInterface>
            <mechanicalReduction>1</mechanicalReduction>
        </actuator>
    </transmission>
    <transmission name="stickbug/arm5/trans_e1">
        <type>transmission_interface/SimpleTransmission</type>
        <joint name="stickbug/arm5/e1">
            <hardwareInterface>hardware_interface/EffortJointInterface</hardwareInterface>
        </joint>
        <actuator name="stickbug/arm5/e1_motor">
            <hardwareInterface>hardware_interface/EffortJointInterface</hardwareInterface>
            <mechanicalReduction>1</mechanicalReduction>
        </actuator>
    </transmission>
    <transmission name="stickbug/arm5/trans_e2">
        <type>transmission_interface/SimpleTransmission</type>
        <joint name="stickbug/arm5/e2">
            <hardwareInterface>hardware_interface/EffortJointInterface</hardwareInterface>
        </joint>
        <actuator name="stickbug/arm5/e2_motor">
            <hardwareInterface>hardware_interface/EffortJointInterface</hardwareInterface>
            <mechanicalReduction>1</mechanicalReduction>
        </actuator>
    </transmission>
    <transmission name="stickbug/arm5/trans_e3">
        <type>transmission_interface/SimpleTransmission</type>
        <joint name="stickbug/arm5/e3">
            <hardwareInterface>hardware_interface/EffortJointInterface</hardwareInterface>
        </joint>
        <actuator name="stickbug/arm5/e3_motor">
            <hardwareInterface>hardware_interface/EffortJointInterface</hardwareInterface>
            <mechanicalReduction>1</mechanicalReduction>
        </actuator>
    </transmission>
    <!--================================ right realsense plugin ================================-->
    <gazebo reference="stickbug/arm5/cam_link">
        <sensor name="stickbug/arm5/cam_link_camera" type="depth">
            <update_rate>20</update_rate>
            <camera>
                <horizontal_fov>1.047198</horizontal_fov>
                <image>
                    <width>640</width>
                    <height>480</height>
                    <format>R8G8B8</format>
                </image>
                <clip>
                    <near>0.05</near>
                    <far>3</far>
                </clip>
            </camera>
            <plugin filename="libgazebo_ros_openni_kinect.so" name="stickbug/arm5/cam_link_controller">
                <baseline>0.2</baseline>
                <alwaysOn>true</alwaysOn>
                <updateRate>1.0</updateRate>
                <cameraName>stickbug/arm5/cam_link</cameraName>
                <imageTopicName>color/image_raw</imageTopicName>
                <cameraInfoTopicName>color/camera_info</cameraInfoTopicName>
                <depthImageTopicName>depth/image_raw</depthImageTopicName>
                <depthImageInfoTopicName>depth/camera_info</depthImageInfoTopicName>
                <pointCloudTopicName>depth/points</pointCloudTopicName>
                <frameName>stickbug/arm5/camera_frame</frameName>
                <pointCloudCutoff>0.5</pointCloudCutoff>
                <pointCloudCutoffMax>3.0</pointCloudCutoffMax>
                <distortionK1>0.00000001</distortionK1>
                <distortionK2>0.00000001</distortionK2>
                <distortionK3>0.00000001</distortionK3>
                <distortionT1>0.00000001</distortionT1>
                <distortionT2>0.00000001</distortionT2>
                <CxPrime>0</CxPrime>
                <Cx>0</Cx>
                <Cy>0</Cy>
                <focalLength>0</focalLength>
                <hackBaseline>0</hackBaseline>
            </plugin>
        </sensor>
    </gazebo>
    <link name="stickbug/arm2/box">
        <inertial>
            <origin rpy="0 0 0" xyz="-0.0294836466854795 -0.00650699178978333 0.054665921342337" />
            <mass value="1.25224595398726" />
            <inertia ixx="0.00206596064394956" ixy="0.000334896166615364" ixz="-0.000136948453654299" iyy="0.0035115970252851" iyz="-4.17254634185766E-05" izz="0.00431158338218049" />
        </inertial>
        <visual>
            <origin rpy="0 0 0" xyz="0 0 0" />
            <geometry>
                <mesh filename="package://poll_arm_right/meshes/box.STL" />
            </geometry>
            <material name="">
                <color rgba="0.792156862745098 0.819607843137255 0.933333333333333 1" />
            </material>
        </visual>
        <collision>
            <origin rpy="0 0 0" xyz="0 0 0" />
            <geometry>
                <mesh filename="package://poll_arm_right/meshes/box.STL" />
            </geometry>
        </collision>
    </link>
    <joint name="stickbug/arm2/slider" type="prismatic">
        <origin rpy="0 0 0" xyz="0 0 0" />
        <parent link="stickbug/drivebase/r_lift" />
        <child link="stickbug/arm2/box" />
        <axis xyz="0 0 1" />
        <limit effort="200" lower="0" upper="2" velocity="0" />
        <dynamics damping="0.2" friction="0.2" />
    </joint>
    <link name="stickbug/arm2/bicep">
        <inertial>
            <origin rpy="0 0 0" xyz="0.19577236492752 0.025617006022445 0.031470242482028" />
            <mass value="0.0881583450015477" />
            <inertia ixx="4.02190655717306E-05" ixy="-9.41441514101079E-09" ixz="-4.66388635592039E-08" iyy="2.35490419805005E-05" iyz="-9.36030697866667E-08" izz="3.32834464790013E-05" />
        </inertial>
        <visual>
            <origin rpy="0 0 0" xyz="0 0 0" />
            <geometry>
                <mesh filename="package://poll_arm_right/meshes/bicep.STL" />
            </geometry>
            <material name="">
                <color rgba="0.698039215686274 0.698039215686274 0.698039215686274 1" />
            </material>
        </visual>
        <collision>
            <origin rpy="0 0 0" xyz="0 0 0" />
            <geometry>
                <mesh filename="package://poll_arm_right/meshes/bicep.STL" />
            </geometry>
        </collision>
    </link>
    <joint name="stickbug/arm2/shoulder" type="revolute">
        <origin rpy="0 0 -0.523598775598304" xyz="0.101983673651571 -0.0444010956927517 0.0186529999998991" />
        <parent link="stickbug/arm2/box" />
        <child link="stickbug/arm2/bicep" />
        <axis xyz="0 0 1" />
        <limit effort="200" lower="-1.57" upper="1.57" velocity="0" />
        <dynamics damping="0.2" friction="0.2" />
    </joint>
    <link name="stickbug/arm2/forearm">
        <inertial>
            <origin rpy="0 0 0" xyz="0.0765243373190801 -0.00763087662935313 0.0278615390492158" />
            <mass value="0.0881583450015477" />
            <inertia ixx="4.02190655717306E-05" ixy="-9.41441514101079E-09" ixz="-4.66388635592039E-08" iyy="2.35490419805005E-05" iyz="-9.36030697866667E-08" izz="3.32834464790013E-05" />
        </inertial>
        <visual>
            <origin rpy="0 0 0" xyz="0 0 0" />
            <geometry>
                <mesh filename="package://poll_arm_right/meshes/forearm.STL" />
            </geometry>
            <material name="">
                <color rgba="0.698039215686274 0.698039215686274 0.698039215686274 1" />
            </material>
        </visual>
        <collision>
            <origin rpy="0 0 0" xyz="0 0 0" />
            <geometry>
                <mesh filename="package://poll_arm_right/meshes/forearm.STL" />
            </geometry>
        </collision>
    </link>
    <joint name="stickbug/arm2/elbow" type="revolute">
        <origin rpy="0 0 1.5707963267949" xyz="0.1959 0.0406860000000015 0.00350608116532053" />
        <parent link="stickbug/arm2/bicep" />
        <child link="stickbug/arm2/forearm" />
        <axis xyz="0 0 1" />
        <limit effort="200" lower="-1.57" upper="1.57" velocity="0" />
        <dynamics damping="0.2" friction="0.2" />
    </joint>
    <link name="stickbug/arm2/w1_link">
        <inertial>
            <origin rpy="0 0 0" xyz="0.0119998492953422 -0.000549087822445449 0.0216260058358662" />
            <mass value="0.0565320862795783" />
            <inertia ixx="1.0226625085126E-05" ixy="6.10475234160948E-10" ixz="-7.97796107526925E-10" iyy="1.43894864274769E-05" iyz="3.44003507752819E-07" izz="1.4389503019841E-05" />
        </inertial>
        <visual>
            <origin rpy="0 0 0" xyz="0 0 0" />
            <geometry>
                <mesh filename="package://poll_arm_right/meshes/w1_link.STL" />
            </geometry>
            <material name="">
                <color rgba="0.792156862745098 0.819607843137255 0.933333333333333 1" />
            </material>
        </visual>
        <collision>
            <origin rpy="0 0 0" xyz="0 0 0" />
            <geometry>
                <mesh filename="package://poll_arm_right/meshes/w1_link.STL" />
            </geometry>
        </collision>
    </link>
    <joint name="stickbug/arm2/w1" type="revolute">
        <origin rpy="0 0 0" xyz="0.154351347 0 0.00586118891519596" />
        <parent link="stickbug/arm2/forearm" />
        <child link="stickbug/arm2/w1_link" />
        <axis xyz="0 0 1" />
        <limit effort="200" lower="-1.57" upper="1.57" velocity="0" />
        <dynamics damping="0.2" friction="0.2" />
    </joint>
    <link name="stickbug/arm2/w2_link">
        <inertial>
            <origin rpy="0 0 0" xyz="0.0566451733011976 -0.00141725658574912 0.0284323416048118" />
            <mass value="0.153757182920479" />
            <inertia ixx="9.61201704567482E-05" ixy="-2.53181854057694E-06" ixz="1.28235405708061E-05" iyy="0.000113585627853035" iyz="-2.70973268265225E-06" izz="6.51970121574257E-05" />
        </inertial>
        <visual>
            <origin rpy="0 0 0" xyz="0 0 0" />
            <geometry>
                <mesh filename="package://poll_arm_right/meshes/w2_link.STL" />
            </geometry>
            <material name="">
                <color rgba="0.792156862745098 0.819607843137255 0.933333333333333 1" />
            </material>
        </visual>
        <collision>
            <origin rpy="0 0 0" xyz="0 0 0" />
            <geometry>
                <mesh filename="package://poll_arm_right/meshes/w2_link.STL" />
            </geometry>
        </collision>
    </link>
    <joint name="stickbug/arm2/w2" type="revolute">
        <origin rpy="1.57079632679489 0 0" xyz="0.0240000007161376 0.0221999998475506 0.0221750001524488" />
        <parent link="stickbug/arm2/w1_link" />
        <child link="stickbug/arm2/w2_link" />
        <axis xyz="0 0 1" />
        <limit effort="200" lower="-1.57" upper="1.57" velocity="0" />
        <dynamics damping="0.2" friction="0.2" />
    </joint>
    <link name="stickbug/arm2/cam_link">
        <inertial>
            <origin rpy="0 0 0" xyz="-0.0113814657659484 -3.7765632954212E-08 -8.96828082674883E-05" />
            <mass value="0.0394840464043759" />
            <inertia ixx="1.13008734896739E-05" ixy="-1.18403271942562E-12" ixz="-1.11849815558335E-08" iyy="7.34442345562824E-06" iyz="2.14724251236641E-11" izz="7.39890475454631E-06" />
        </inertial>
        <visual>
            <origin rpy="0 0 0" xyz="0 0 0" />
            <geometry>
                <mesh filename="package://poll_arm_right/meshes/cam_link.STL" />
            </geometry>
            <material name="">
                <color rgba="0.792156862745098 0.819607843137255 0.933333333333333 1" />
            </material>
        </visual>
        <collision>
            <origin rpy="0 0 0" xyz="0 0 0" />
            <geometry>
                <mesh filename="package://poll_arm_right/meshes/cam_link.STL" />
            </geometry>
        </collision>
    </link>
    <joint name="stickbug/arm2/cam_joint" type="fixed">
        <origin rpy="0 0.26179938779915 0" xyz="0.063863151034262 0 0.0834316043147122" />
        <parent link="stickbug/arm2/w2_link" />
        <child link="stickbug/arm2/cam_link" />
        <axis xyz="0 0 0" />
    </joint>
    <link name="stickbug/arm2/e1_link">
        <inertial>
            <origin rpy="0 0 0" xyz="0.00768377159854672 0.00530600599131259 -0.000730992899423522" />
            <mass value="0.00225996756513805" />
            <inertia ixx="1.30412723697187E-07" ixy="9.73218559749733E-08" ixz="2.16169394663048E-08" iyy="1.966205244536E-07" iyz="-1.2986245459416E-08" izz="3.15647081687985E-07" />
        </inertial>
        <visual>
            <origin rpy="0 0 0" xyz="0 0 0" />
            <geometry>
                <mesh filename="package://poll_arm_right/meshes/e1_link.STL" />
            </geometry>
            <material name="">
                <color rgba="0.792156862745098 0.819607843137255 0.933333333333333 1" />
            </material>
        </visual>
        <collision>
            <origin rpy="0 0 0" xyz="0 0 0" />
            <geometry>
                <mesh filename="package://poll_arm_right/meshes/e1_link.STL" />
            </geometry>
        </collision>
    </link>
    <joint name="stickbug/arm2/e1" type="revolute">
        <origin rpy="-1.0471975511966 0 0" xyz="0.0769999999999999 0.0112634866641177 0.00700070249463941" />
        <parent link="stickbug/arm2/w2_link" />
        <child link="stickbug/arm2/e1_link" />
        <axis xyz="0 0 1" />
        <limit effort="200" lower="-1.57" upper="1.57" velocity="0" />
        <dynamics damping="0.2" friction="0.2" />
    </joint>
    <link name="stickbug/arm2/e2_link">
        <inertial>
            <origin rpy="0 0 0" xyz="0.0076837715993977 0.00530600599028458 -0.000730992897713667" />
            <mass value="0.00225996756505407" />
            <inertia ixx="1.30412723709295E-07" ixy="9.73218559904026E-08" ixz="2.16169394327849E-08" iyy="1.96620524444531E-07" iyz="-1.2986245443103E-08" izz="3.15647081713528E-07" />
        </inertial>
        <visual>
            <origin rpy="0 0 0" xyz="0 0 0" />
            <geometry>
                <mesh filename="package://poll_arm_right/meshes/e2_link.STL" />
            </geometry>
            <material name="">
                <color rgba="0.250980392156863 0.250980392156863 0.250980392156863 1" />
            </material>
        </visual>
        <collision>
            <origin rpy="0 0 0" xyz="0 0 0" />
            <geometry>
                <mesh filename="package://poll_arm_right/meshes/e2_link.STL" />
            </geometry>
        </collision>
    </link>
    <joint name="stickbug/arm2/e2" type="revolute">
        <origin rpy="1.0472 0 0" xyz="0.077 0.0074446 0.039404" />
        <parent link="stickbug/arm2/w2_link" />
        <child link="stickbug/arm2/e2_link" />
        <axis xyz="0 0 1" />
        <limit effort="200" lower="-1.57" upper="1.57" velocity="0" />
        <dynamics damping="0.2" friction="0.2" />
    </joint>
    <link name="stickbug/arm2/e3_link">
        <inertial>
            <origin rpy="0 0 0" xyz="0.00768377159880046 0.00530600599161379 -0.000730992902174266" />
            <mass value="0.00225996756527348" />
            <inertia ixx="1.30412723718879E-07" ixy="9.73218559573204E-08" ixz="2.16169395180174E-08" iyy="1.96620524429934E-07" iyz="-1.2986245490849E-08" izz="3.15647081641822E-07" />
        </inertial>
        <visual>
            <origin rpy="0 0 0" xyz="0 0 0" />
            <geometry>
                <mesh filename="package://poll_arm_right/meshes/e3_link.STL" />
            </geometry>
            <material name="">
                <color rgba="0.250980392156863 0.250980392156863 0.250980392156863 1" />
            </material>
        </visual>
        <collision>
            <origin rpy="0 0 0" xyz="0 0 0" />
            <geometry>
                <mesh filename="package://poll_arm_right/meshes/e3_link.STL" />
            </geometry>
        </collision>
    </link>
    <joint name="stickbug/arm2/e3" type="revolute">
        <origin rpy="3.14159265358979 0 0" xyz="0.077000000000051 -0.0187081185534836 0.0198951831632689" />
        <parent link="stickbug/arm2/w2_link" />
        <child link="stickbug/arm2/e3_link" />
        <axis xyz="0 0 1" />
        <limit effort="200" lower="-1.57" upper="1.57" velocity="0" />
        <dynamics damping="0.2" friction="0.2" />
    </joint>
    <link name="stickbug/arm2/end_link">
        <inertial>
            <origin rpy="0 0 0" xyz="-0.00224236893916036 -3.51872006532084E-08 3.59307923136765E-08" />
            <mass value="0.00244973338644466" />
            <inertia ixx="2.17281683587081E-07" ixy="1.95917302230901E-13" ixz="-3.07605742822788E-13" iyy="1.14231479742373E-07" iyz="9.90134628090014E-13" izz="1.14231411420647E-07" />
        </inertial>
        <visual>
            <origin rpy="0 0 0" xyz="0 0 0" />
            <geometry>
                <mesh filename="package://poll_arm_right/meshes/end_link.STL" />
            </geometry>
            <material name="">
                <color rgba="0.792156862745098 0.819607843137255 0.933333333333333 1" />
            </material>
        </visual>
        <collision>
            <origin rpy="0 0 0" xyz="0 0 0" />
            <geometry>
                <mesh filename="package://poll_arm_right/meshes/end_link.STL" />
            </geometry>
        </collision>
    </link>
    <joint name="stickbug/arm2/end_joint" type="fixed">
        <origin rpy="-1.57079632679491 0 0" xyz="0.122934886777477 0 0.0220999999985055" />
        <parent link="stickbug/arm2/w2_link" />
        <child link="stickbug/arm2/end_link" />
        <axis xyz="0 0 0" />
    </joint>
    <link name="stickbug/arm2/camera_frame" />
    <joint name="stickbug/arm2/cam_link2cam_frame" type="fixed">
        <parent link="stickbug/arm2/cam_link" />
        <child link="stickbug/arm2/camera_frame" />
        <origin rpy="-1.57 0.0 -1.57" xyz="0.0 0.0 0.0" />
    </joint>
    <transmission name="stickbug/arm2/trans_slider">
        <type>transmission_interface/SimpleTransmission</type>
        <joint name="stickbug/arm2/slider">
            <hardwareInterface>hardware_interface/EffortJointInterface</hardwareInterface>
        </joint>
        <actuator name="stickbug/arm2/slider_motor">
            <hardwareInterface>hardware_interface/EffortJointInterface</hardwareInterface>
            <mechanicalReduction>1</mechanicalReduction>
        </actuator>
    </transmission>
    <transmission name="stickbug/arm2/trans_shoulder">
        <type>transmission_interface/SimpleTransmission</type>
        <joint name="stickbug/arm2/shoulder">
            <hardwareInterface>hardware_interface/EffortJointInterface</hardwareInterface>
        </joint>
        <actuator name="stickbug/arm2/shoulder_motor">
            <hardwareInterface>hardware_interface/EffortJointInterface</hardwareInterface>
            <mechanicalReduction>1</mechanicalReduction>
        </actuator>
    </transmission>
    <transmission name="stickbug/arm2/trans_elbow">
        <type>transmission_interface/SimpleTransmission</type>
        <joint name="stickbug/arm2/elbow">
            <hardwareInterface>hardware_interface/EffortJointInterface</hardwareInterface>
        </joint>
        <actuator name="stickbug/arm2/elbow_motor">
            <hardwareInterface>hardware_interface/EffortJointInterface</hardwareInterface>
            <mechanicalReduction>1</mechanicalReduction>
        </actuator>
    </transmission>
    <transmission name="stickbug/arm2/trans_w1">
        <type>transmission_interface/SimpleTransmission</type>
        <joint name="stickbug/arm2/w1">
            <hardwareInterface>hardware_interface/EffortJointInterface</hardwareInterface>
        </joint>
        <actuator name="stickbug/arm2/w1_motor">
            <hardwareInterface>hardware_interface/EffortJointInterface</hardwareInterface>
            <mechanicalReduction>1</mechanicalReduction>
        </actuator>
    </transmission>
    <transmission name="stickbug/arm2/trans_w2">
        <type>transmission_interface/SimpleTransmission</type>
        <joint name="stickbug/arm2/w2">
            <hardwareInterface>hardware_interface/EffortJointInterface</hardwareInterface>
        </joint>
        <actuator name="stickbug/arm2/w2_motor">
            <hardwareInterface>hardware_interface/EffortJointInterface</hardwareInterface>
            <mechanicalReduction>1</mechanicalReduction>
        </actuator>
    </transmission>
    <transmission name="stickbug/arm2/trans_e1">
        <type>transmission_interface/SimpleTransmission</type>
        <joint name="stickbug/arm2/e1">
            <hardwareInterface>hardware_interface/EffortJointInterface</hardwareInterface>
        </joint>
        <actuator name="stickbug/arm2/e1_motor">
            <hardwareInterface>hardware_interface/EffortJointInterface</hardwareInterface>
            <mechanicalReduction>1</mechanicalReduction>
        </actuator>
    </transmission>
    <transmission name="stickbug/arm2/trans_e2">
        <type>transmission_interface/SimpleTransmission</type>
        <joint name="stickbug/arm2/e2">
            <hardwareInterface>hardware_interface/EffortJointInterface</hardwareInterface>
        </joint>
        <actuator name="stickbug/arm2/e2_motor">
            <hardwareInterface>hardware_interface/EffortJointInterface</hardwareInterface>
            <mechanicalReduction>1</mechanicalReduction>
        </actuator>
    </transmission>
    <transmission name="stickbug/arm2/trans_e3">
        <type>transmission_interface/SimpleTransmission</type>
        <joint name="stickbug/arm2/e3">
            <hardwareInterface>hardware_interface/EffortJointInterface</hardwareInterface>
        </joint>
        <actuator name="stickbug/arm2/e3_motor">
            <hardwareInterface>hardware_interface/EffortJointInterface</hardwareInterface>
            <mechanicalReduction>1</mechanicalReduction>
        </actuator>
    </transmission>
    <!--================================ right realsense plugin ================================-->
    <gazebo reference="stickbug/arm2/cam_link">
        <sensor name="stickbug/arm2/cam_link_camera" type="depth">
            <update_rate>20</update_rate>
            <camera>
                <horizontal_fov>1.047198</horizontal_fov>
                <image>
                    <width>640</width>
                    <height>480</height>
                    <format>R8G8B8</format>
                </image>
                <clip>
                    <near>0.05</near>
                    <far>3</far>
                </clip>
            </camera>
            <plugin filename="libgazebo_ros_openni_kinect.so" name="stickbug/arm2/cam_link_controller">
                <baseline>0.2</baseline>
                <alwaysOn>true</alwaysOn>
                <updateRate>1.0</updateRate>
                <cameraName>stickbug/arm2/cam_link</cameraName>
                <imageTopicName>color/image_raw</imageTopicName>
                <cameraInfoTopicName>color/camera_info</cameraInfoTopicName>
                <depthImageTopicName>depth/image_raw</depthImageTopicName>
                <depthImageInfoTopicName>depth/camera_info</depthImageInfoTopicName>
                <pointCloudTopicName>depth/points</pointCloudTopicName>
                <frameName>stickbug/arm2/camera_frame</frameName>
                <pointCloudCutoff>0.5</pointCloudCutoff>
                <pointCloudCutoffMax>3.0</pointCloudCutoffMax>
                <distortionK1>0.00000001</distortionK1>
                <distortionK2>0.00000001</distortionK2>
                <distortionK3>0.00000001</distortionK3>
                <distortionT1>0.00000001</distortionT1>
                <distortionT2>0.00000001</distortionT2>
                <CxPrime>0</CxPrime>
                <Cx>0</Cx>
                <Cy>0</Cy>
                <focalLength>0</focalLength>
                <hackBaseline>0</hackBaseline>
            </plugin>
        </sensor>
    </gazebo>
    <link name="stickbug/arm4/box">
        <inertial>
            <origin rpy="0 0 0" xyz="-0.0294836466854795 -0.00650699178978333 0.054665921342337" />
            <mass value="1.25224595398726" />
            <inertia ixx="0.00206596064394956" ixy="0.000334896166615364" ixz="-0.000136948453654299" iyy="0.0035115970252851" iyz="-4.17254634185766E-05" izz="0.00431158338218049" />
        </inertial>
        <visual>
            <origin rpy="0 0 0" xyz="0 0 0" />
            <geometry>
                <mesh filename="package://poll_arm_right/meshes/box.STL" />
            </geometry>
            <material name="">
                <color rgba="0.792156862745098 0.819607843137255 0.933333333333333 1" />
            </material>
        </visual>
        <collision>
            <origin rpy="0 0 0" xyz="0 0 0" />
            <geometry>
                <mesh filename="package://poll_arm_right/meshes/box.STL" />
            </geometry>
        </collision>
    </link>
    <joint name="stickbug/arm4/slider" type="prismatic">
        <origin rpy="0 0 0" xyz="0 0 0" />
        <parent link="stickbug/drivebase/r_lift" />
        <child link="stickbug/arm4/box" />
        <axis xyz="0 0 1" />
        <limit effort="200" lower="0" upper="2" velocity="0" />
        <dynamics damping="0.2" friction="0.2" />
    </joint>
    <link name="stickbug/arm4/bicep">
        <inertial>
            <origin rpy="0 0 0" xyz="0.19577236492752 0.025617006022445 0.031470242482028" />
            <mass value="0.0881583450015477" />
            <inertia ixx="4.02190655717306E-05" ixy="-9.41441514101079E-09" ixz="-4.66388635592039E-08" iyy="2.35490419805005E-05" iyz="-9.36030697866667E-08" izz="3.32834464790013E-05" />
        </inertial>
        <visual>
            <origin rpy="0 0 0" xyz="0 0 0" />
            <geometry>
                <mesh filename="package://poll_arm_right/meshes/bicep.STL" />
            </geometry>
            <material name="">
                <color rgba="0.698039215686274 0.698039215686274 0.698039215686274 1" />
            </material>
        </visual>
        <collision>
            <origin rpy="0 0 0" xyz="0 0 0" />
            <geometry>
                <mesh filename="package://poll_arm_right/meshes/bicep.STL" />
            </geometry>
        </collision>
    </link>
    <joint name="stickbug/arm4/shoulder" type="revolute">
        <origin rpy="0 0 -0.523598775598304" xyz="0.101983673651571 -0.0444010956927517 0.0186529999998991" />
        <parent link="stickbug/arm4/box" />
        <child link="stickbug/arm4/bicep" />
        <axis xyz="0 0 1" />
        <limit effort="200" lower="-1.57" upper="1.57" velocity="0" />
        <dynamics damping="0.2" friction="0.2" />
    </joint>
    <link name="stickbug/arm4/forearm">
        <inertial>
            <origin rpy="0 0 0" xyz="0.0765243373190801 -0.00763087662935313 0.0278615390492158" />
            <mass value="0.0881583450015477" />
            <inertia ixx="4.02190655717306E-05" ixy="-9.41441514101079E-09" ixz="-4.66388635592039E-08" iyy="2.35490419805005E-05" iyz="-9.36030697866667E-08" izz="3.32834464790013E-05" />
        </inertial>
        <visual>
            <origin rpy="0 0 0" xyz="0 0 0" />
            <geometry>
                <mesh filename="package://poll_arm_right/meshes/forearm.STL" />
            </geometry>
            <material name="">
                <color rgba="0.698039215686274 0.698039215686274 0.698039215686274 1" />
            </material>
        </visual>
        <collision>
            <origin rpy="0 0 0" xyz="0 0 0" />
            <geometry>
                <mesh filename="package://poll_arm_right/meshes/forearm.STL" />
            </geometry>
        </collision>
    </link>
    <joint name="stickbug/arm4/elbow" type="revolute">
        <origin rpy="0 0 1.5707963267949" xyz="0.1959 0.0406860000000015 0.00350608116532053" />
        <parent link="stickbug/arm4/bicep" />
        <child link="stickbug/arm4/forearm" />
        <axis xyz="0 0 1" />
        <limit effort="200" lower="-1.57" upper="1.57" velocity="0" />
        <dynamics damping="0.2" friction="0.2" />
    </joint>
    <link name="stickbug/arm4/w1_link">
        <inertial>
            <origin rpy="0 0 0" xyz="0.0119998492953422 -0.000549087822445449 0.0216260058358662" />
            <mass value="0.0565320862795783" />
            <inertia ixx="1.0226625085126E-05" ixy="6.10475234160948E-10" ixz="-7.97796107526925E-10" iyy="1.43894864274769E-05" iyz="3.44003507752819E-07" izz="1.4389503019841E-05" />
        </inertial>
        <visual>
            <origin rpy="0 0 0" xyz="0 0 0" />
            <geometry>
                <mesh filename="package://poll_arm_right/meshes/w1_link.STL" />
            </geometry>
            <material name="">
                <color rgba="0.792156862745098 0.819607843137255 0.933333333333333 1" />
            </material>
        </visual>
        <collision>
            <origin rpy="0 0 0" xyz="0 0 0" />
            <geometry>
                <mesh filename="package://poll_arm_right/meshes/w1_link.STL" />
            </geometry>
        </collision>
    </link>
    <joint name="stickbug/arm4/w1" type="revolute">
        <origin rpy="0 0 0" xyz="0.154351347 0 0.00586118891519596" />
        <parent link="stickbug/arm4/forearm" />
        <child link="stickbug/arm4/w1_link" />
        <axis xyz="0 0 1" />
        <limit effort="200" lower="-1.57" upper="1.57" velocity="0" />
        <dynamics damping="0.2" friction="0.2" />
    </joint>
    <link name="stickbug/arm4/w2_link">
        <inertial>
            <origin rpy="0 0 0" xyz="0.0566451733011976 -0.00141725658574912 0.0284323416048118" />
            <mass value="0.153757182920479" />
            <inertia ixx="9.61201704567482E-05" ixy="-2.53181854057694E-06" ixz="1.28235405708061E-05" iyy="0.000113585627853035" iyz="-2.70973268265225E-06" izz="6.51970121574257E-05" />
        </inertial>
        <visual>
            <origin rpy="0 0 0" xyz="0 0 0" />
            <geometry>
                <mesh filename="package://poll_arm_right/meshes/w2_link.STL" />
            </geometry>
            <material name="">
                <color rgba="0.792156862745098 0.819607843137255 0.933333333333333 1" />
            </material>
        </visual>
        <collision>
            <origin rpy="0 0 0" xyz="0 0 0" />
            <geometry>
                <mesh filename="package://poll_arm_right/meshes/w2_link.STL" />
            </geometry>
        </collision>
    </link>
    <joint name="stickbug/arm4/w2" type="revolute">
        <origin rpy="1.57079632679489 0 0" xyz="0.0240000007161376 0.0221999998475506 0.0221750001524488" />
        <parent link="stickbug/arm4/w1_link" />
        <child link="stickbug/arm4/w2_link" />
        <axis xyz="0 0 1" />
        <limit effort="200" lower="-1.57" upper="1.57" velocity="0" />
        <dynamics damping="0.2" friction="0.2" />
    </joint>
    <link name="stickbug/arm4/cam_link">
        <inertial>
            <origin rpy="0 0 0" xyz="-0.0113814657659484 -3.7765632954212E-08 -8.96828082674883E-05" />
            <mass value="0.0394840464043759" />
            <inertia ixx="1.13008734896739E-05" ixy="-1.18403271942562E-12" ixz="-1.11849815558335E-08" iyy="7.34442345562824E-06" iyz="2.14724251236641E-11" izz="7.39890475454631E-06" />
        </inertial>
        <visual>
            <origin rpy="0 0 0" xyz="0 0 0" />
            <geometry>
                <mesh filename="package://poll_arm_right/meshes/cam_link.STL" />
            </geometry>
            <material name="">
                <color rgba="0.792156862745098 0.819607843137255 0.933333333333333 1" />
            </material>
        </visual>
        <collision>
            <origin rpy="0 0 0" xyz="0 0 0" />
            <geometry>
                <mesh filename="package://poll_arm_right/meshes/cam_link.STL" />
            </geometry>
        </collision>
    </link>
    <joint name="stickbug/arm4/cam_joint" type="fixed">
        <origin rpy="0 0.26179938779915 0" xyz="0.063863151034262 0 0.0834316043147122" />
        <parent link="stickbug/arm4/w2_link" />
        <child link="stickbug/arm4/cam_link" />
        <axis xyz="0 0 0" />
    </joint>
    <link name="stickbug/arm4/e1_link">
        <inertial>
            <origin rpy="0 0 0" xyz="0.00768377159854672 0.00530600599131259 -0.000730992899423522" />
            <mass value="0.00225996756513805" />
            <inertia ixx="1.30412723697187E-07" ixy="9.73218559749733E-08" ixz="2.16169394663048E-08" iyy="1.966205244536E-07" iyz="-1.2986245459416E-08" izz="3.15647081687985E-07" />
        </inertial>
        <visual>
            <origin rpy="0 0 0" xyz="0 0 0" />
            <geometry>
                <mesh filename="package://poll_arm_right/meshes/e1_link.STL" />
            </geometry>
            <material name="">
                <color rgba="0.792156862745098 0.819607843137255 0.933333333333333 1" />
            </material>
        </visual>
        <collision>
            <origin rpy="0 0 0" xyz="0 0 0" />
            <geometry>
                <mesh filename="package://poll_arm_right/meshes/e1_link.STL" />
            </geometry>
        </collision>
    </link>
    <joint name="stickbug/arm4/e1" type="revolute">
        <origin rpy="-1.0471975511966 0 0" xyz="0.0769999999999999 0.0112634866641177 0.00700070249463941" />
        <parent link="stickbug/arm4/w2_link" />
        <child link="stickbug/arm4/e1_link" />
        <axis xyz="0 0 1" />
        <limit effort="200" lower="-1.57" upper="1.57" velocity="0" />
        <dynamics damping="0.2" friction="0.2" />
    </joint>
    <link name="stickbug/arm4/e2_link">
        <inertial>
            <origin rpy="0 0 0" xyz="0.0076837715993977 0.00530600599028458 -0.000730992897713667" />
            <mass value="0.00225996756505407" />
            <inertia ixx="1.30412723709295E-07" ixy="9.73218559904026E-08" ixz="2.16169394327849E-08" iyy="1.96620524444531E-07" iyz="-1.2986245443103E-08" izz="3.15647081713528E-07" />
        </inertial>
        <visual>
            <origin rpy="0 0 0" xyz="0 0 0" />
            <geometry>
                <mesh filename="package://poll_arm_right/meshes/e2_link.STL" />
            </geometry>
            <material name="">
                <color rgba="0.250980392156863 0.250980392156863 0.250980392156863 1" />
            </material>
        </visual>
        <collision>
            <origin rpy="0 0 0" xyz="0 0 0" />
            <geometry>
                <mesh filename="package://poll_arm_right/meshes/e2_link.STL" />
            </geometry>
        </collision>
    </link>
    <joint name="stickbug/arm4/e2" type="revolute">
        <origin rpy="1.0472 0 0" xyz="0.077 0.0074446 0.039404" />
        <parent link="stickbug/arm4/w2_link" />
        <child link="stickbug/arm4/e2_link" />
        <axis xyz="0 0 1" />
        <limit effort="200" lower="-1.57" upper="1.57" velocity="0" />
        <dynamics damping="0.2" friction="0.2" />
    </joint>
    <link name="stickbug/arm4/e3_link">
        <inertial>
            <origin rpy="0 0 0" xyz="0.00768377159880046 0.00530600599161379 -0.000730992902174266" />
            <mass value="0.00225996756527348" />
            <inertia ixx="1.30412723718879E-07" ixy="9.73218559573204E-08" ixz="2.16169395180174E-08" iyy="1.96620524429934E-07" iyz="-1.2986245490849E-08" izz="3.15647081641822E-07" />
        </inertial>
        <visual>
            <origin rpy="0 0 0" xyz="0 0 0" />
            <geometry>
                <mesh filename="package://poll_arm_right/meshes/e3_link.STL" />
            </geometry>
            <material name="">
                <color rgba="0.250980392156863 0.250980392156863 0.250980392156863 1" />
            </material>
        </visual>
        <collision>
            <origin rpy="0 0 0" xyz="0 0 0" />
            <geometry>
                <mesh filename="package://poll_arm_right/meshes/e3_link.STL" />
            </geometry>
        </collision>
    </link>
    <joint name="stickbug/arm4/e3" type="revolute">
        <origin rpy="3.14159265358979 0 0" xyz="0.077000000000051 -0.0187081185534836 0.0198951831632689" />
        <parent link="stickbug/arm4/w2_link" />
        <child link="stickbug/arm4/e3_link" />
        <axis xyz="0 0 1" />
        <limit effort="200" lower="-1.57" upper="1.57" velocity="0" />
        <dynamics damping="0.2" friction="0.2" />
    </joint>
    <link name="stickbug/arm4/end_link">
        <inertial>
            <origin rpy="0 0 0" xyz="-0.00224236893916036 -3.51872006532084E-08 3.59307923136765E-08" />
            <mass value="0.00244973338644466" />
            <inertia ixx="2.17281683587081E-07" ixy="1.95917302230901E-13" ixz="-3.07605742822788E-13" iyy="1.14231479742373E-07" iyz="9.90134628090014E-13" izz="1.14231411420647E-07" />
        </inertial>
        <visual>
            <origin rpy="0 0 0" xyz="0 0 0" />
            <geometry>
                <mesh filename="package://poll_arm_right/meshes/end_link.STL" />
            </geometry>
            <material name="">
                <color rgba="0.792156862745098 0.819607843137255 0.933333333333333 1" />
            </material>
        </visual>
        <collision>
            <origin rpy="0 0 0" xyz="0 0 0" />
            <geometry>
                <mesh filename="package://poll_arm_right/meshes/end_link.STL" />
            </geometry>
        </collision>
    </link>
    <joint name="stickbug/arm4/end_joint" type="fixed">
        <origin rpy="-1.57079632679491 0 0" xyz="0.122934886777477 0 0.0220999999985055" />
        <parent link="stickbug/arm4/w2_link" />
        <child link="stickbug/arm4/end_link" />
        <axis xyz="0 0 0" />
    </joint>
    <link name="stickbug/arm4/camera_frame" />
    <joint name="stickbug/arm4/cam_link2cam_frame" type="fixed">
        <parent link="stickbug/arm4/cam_link" />
        <child link="stickbug/arm4/camera_frame" />
        <origin rpy="-1.57 0.0 -1.57" xyz="0.0 0.0 0.0" />
    </joint>
    <transmission name="stickbug/arm4/trans_slider">
        <type>transmission_interface/SimpleTransmission</type>
        <joint name="stickbug/arm4/slider">
            <hardwareInterface>hardware_interface/EffortJointInterface</hardwareInterface>
        </joint>
        <actuator name="stickbug/arm4/slider_motor">
            <hardwareInterface>hardware_interface/EffortJointInterface</hardwareInterface>
            <mechanicalReduction>1</mechanicalReduction>
        </actuator>
    </transmission>
    <transmission name="stickbug/arm4/trans_shoulder">
        <type>transmission_interface/SimpleTransmission</type>
        <joint name="stickbug/arm4/shoulder">
            <hardwareInterface>hardware_interface/EffortJointInterface</hardwareInterface>
        </joint>
        <actuator name="stickbug/arm4/shoulder_motor">
            <hardwareInterface>hardware_interface/EffortJointInterface</hardwareInterface>
            <mechanicalReduction>1</mechanicalReduction>
        </actuator>
    </transmission>
    <transmission name="stickbug/arm4/trans_elbow">
        <type>transmission_interface/SimpleTransmission</type>
        <joint name="stickbug/arm4/elbow">
            <hardwareInterface>hardware_interface/EffortJointInterface</hardwareInterface>
        </joint>
        <actuator name="stickbug/arm4/elbow_motor">
            <hardwareInterface>hardware_interface/EffortJointInterface</hardwareInterface>
            <mechanicalReduction>1</mechanicalReduction>
        </actuator>
    </transmission>
    <transmission name="stickbug/arm4/trans_w1">
        <type>transmission_interface/SimpleTransmission</type>
        <joint name="stickbug/arm4/w1">
            <hardwareInterface>hardware_interface/EffortJointInterface</hardwareInterface>
        </joint>
        <actuator name="stickbug/arm4/w1_motor">
            <hardwareInterface>hardware_interface/EffortJointInterface</hardwareInterface>
            <mechanicalReduction>1</mechanicalReduction>
        </actuator>
    </transmission>
    <transmission name="stickbug/arm4/trans_w2">
        <type>transmission_interface/SimpleTransmission</type>
        <joint name="stickbug/arm4/w2">
            <hardwareInterface>hardware_interface/EffortJointInterface</hardwareInterface>
        </joint>
        <actuator name="stickbug/arm4/w2_motor">
            <hardwareInterface>hardware_interface/EffortJointInterface</hardwareInterface>
            <mechanicalReduction>1</mechanicalReduction>
        </actuator>
    </transmission>
    <transmission name="stickbug/arm4/trans_e1">
        <type>transmission_interface/SimpleTransmission</type>
        <joint name="stickbug/arm4/e1">
            <hardwareInterface>hardware_interface/EffortJointInterface</hardwareInterface>
        </joint>
        <actuator name="stickbug/arm4/e1_motor">
            <hardwareInterface>hardware_interface/EffortJointInterface</hardwareInterface>
            <mechanicalReduction>1</mechanicalReduction>
        </actuator>
    </transmission>
    <transmission name="stickbug/arm4/trans_e2">
        <type>transmission_interface/SimpleTransmission</type>
        <joint name="stickbug/arm4/e2">
            <hardwareInterface>hardware_interface/EffortJointInterface</hardwareInterface>
        </joint>
        <actuator name="stickbug/arm4/e2_motor">
            <hardwareInterface>hardware_interface/EffortJointInterface</hardwareInterface>
            <mechanicalReduction>1</mechanicalReduction>
        </actuator>
    </transmission>
    <transmission name="stickbug/arm4/trans_e3">
        <type>transmission_interface/SimpleTransmission</type>
        <joint name="stickbug/arm4/e3">
            <hardwareInterface>hardware_interface/EffortJointInterface</hardwareInterface>
        </joint>
        <actuator name="stickbug/arm4/e3_motor">
            <hardwareInterface>hardware_interface/EffortJointInterface</hardwareInterface>
            <mechanicalReduction>1</mechanicalReduction>
        </actuator>
    </transmission>
    <!--================================ right realsense plugin ================================-->
    <gazebo reference="stickbug/arm4/cam_link">
        <sensor name="stickbug/arm4/cam_link_camera" type="depth">
            <update_rate>20</update_rate>
            <camera>
                <horizontal_fov>1.047198</horizontal_fov>
                <image>
                    <width>640</width>
                    <height>480</height>
                    <format>R8G8B8</format>
                </image>
                <clip>
                    <near>0.05</near>
                    <far>3</far>
                </clip>
            </camera>
            <plugin filename="libgazebo_ros_openni_kinect.so" name="stickbug/arm4/cam_link_controller">
                <baseline>0.2</baseline>
                <alwaysOn>true</alwaysOn>
                <updateRate>1.0</updateRate>
                <cameraName>stickbug/arm4/cam_link</cameraName>
                <imageTopicName>color/image_raw</imageTopicName>
                <cameraInfoTopicName>color/camera_info</cameraInfoTopicName>
                <depthImageTopicName>depth/image_raw</depthImageTopicName>
                <depthImageInfoTopicName>depth/camera_info</depthImageInfoTopicName>
                <pointCloudTopicName>depth/points</pointCloudTopicName>
                <frameName>stickbug/arm4/camera_frame</frameName>
                <pointCloudCutoff>0.5</pointCloudCutoff>
                <pointCloudCutoffMax>3.0</pointCloudCutoffMax>
                <distortionK1>0.00000001</distortionK1>
                <distortionK2>0.00000001</distortionK2>
                <distortionK3>0.00000001</distortionK3>
                <distortionT1>0.00000001</distortionT1>
                <distortionT2>0.00000001</distortionT2>
                <CxPrime>0</CxPrime>
                <Cx>0</Cx>
                <Cy>0</Cy>
                <focalLength>0</focalLength>
                <hackBaseline>0</hackBaseline>
            </plugin>
        </sensor>
    </gazebo>
    <link name="stickbug/arm6/box">
        <inertial>
            <origin rpy="0 0 0" xyz="-0.0294836466854795 -0.00650699178978333 0.054665921342337" />
            <mass value="1.25224595398726" />
            <inertia ixx="0.00206596064394956" ixy="0.000334896166615364" ixz="-0.000136948453654299" iyy="0.0035115970252851" iyz="-4.17254634185766E-05" izz="0.00431158338218049" />
        </inertial>
        <visual>
            <origin rpy="0 0 0" xyz="0 0 0" />
            <geometry>
                <mesh filename="package://poll_arm_right/meshes/box.STL" />
            </geometry>
            <material name="">
                <color rgba="0.792156862745098 0.819607843137255 0.933333333333333 1" />
            </material>
        </visual>
        <collision>
            <origin rpy="0 0 0" xyz="0 0 0" />
            <geometry>
                <mesh filename="package://poll_arm_right/meshes/box.STL" />
            </geometry>
        </collision>
    </link>
    <joint name="stickbug/arm6/slider" type="prismatic">
        <origin rpy="0 0 0" xyz="0 0 0" />
        <parent link="stickbug/drivebase/r_lift" />
        <child link="stickbug/arm6/box" />
        <axis xyz="0 0 1" />
        <limit effort="200" lower="0" upper="2" velocity="0" />
        <dynamics damping="0.2" friction="0.2" />
    </joint>
    <link name="stickbug/arm6/bicep">
        <inertial>
            <origin rpy="0 0 0" xyz="0.19577236492752 0.025617006022445 0.031470242482028" />
            <mass value="0.0881583450015477" />
            <inertia ixx="4.02190655717306E-05" ixy="-9.41441514101079E-09" ixz="-4.66388635592039E-08" iyy="2.35490419805005E-05" iyz="-9.36030697866667E-08" izz="3.32834464790013E-05" />
        </inertial>
        <visual>
            <origin rpy="0 0 0" xyz="0 0 0" />
            <geometry>
                <mesh filename="package://poll_arm_right/meshes/bicep.STL" />
            </geometry>
            <material name="">
                <color rgba="0.698039215686274 0.698039215686274 0.698039215686274 1" />
            </material>
        </visual>
        <collision>
            <origin rpy="0 0 0" xyz="0 0 0" />
            <geometry>
                <mesh filename="package://poll_arm_right/meshes/bicep.STL" />
            </geometry>
        </collision>
    </link>
    <joint name="stickbug/arm6/shoulder" type="revolute">
        <origin rpy="0 0 -0.523598775598304" xyz="0.101983673651571 -0.0444010956927517 0.0186529999998991" />
        <parent link="stickbug/arm6/box" />
        <child link="stickbug/arm6/bicep" />
        <axis xyz="0 0 1" />
        <limit effort="200" lower="-1.57" upper="1.57" velocity="0" />
        <dynamics damping="0.2" friction="0.2" />
    </joint>
    <link name="stickbug/arm6/forearm">
        <inertial>
            <origin rpy="0 0 0" xyz="0.0765243373190801 -0.00763087662935313 0.0278615390492158" />
            <mass value="0.0881583450015477" />
            <inertia ixx="4.02190655717306E-05" ixy="-9.41441514101079E-09" ixz="-4.66388635592039E-08" iyy="2.35490419805005E-05" iyz="-9.36030697866667E-08" izz="3.32834464790013E-05" />
        </inertial>
        <visual>
            <origin rpy="0 0 0" xyz="0 0 0" />
            <geometry>
                <mesh filename="package://poll_arm_right/meshes/forearm.STL" />
            </geometry>
            <material name="">
                <color rgba="0.698039215686274 0.698039215686274 0.698039215686274 1" />
            </material>
        </visual>
        <collision>
            <origin rpy="0 0 0" xyz="0 0 0" />
            <geometry>
                <mesh filename="package://poll_arm_right/meshes/forearm.STL" />
            </geometry>
        </collision>
    </link>
    <joint name="stickbug/arm6/elbow" type="revolute">
        <origin rpy="0 0 1.5707963267949" xyz="0.1959 0.0406860000000015 0.00350608116532053" />
        <parent link="stickbug/arm6/bicep" />
        <child link="stickbug/arm6/forearm" />
        <axis xyz="0 0 1" />
        <limit effort="200" lower="-1.57" upper="1.57" velocity="0" />
        <dynamics damping="0.2" friction="0.2" />
    </joint>
    <link name="stickbug/arm6/w1_link">
        <inertial>
            <origin rpy="0 0 0" xyz="0.0119998492953422 -0.000549087822445449 0.0216260058358662" />
            <mass value="0.0565320862795783" />
            <inertia ixx="1.0226625085126E-05" ixy="6.10475234160948E-10" ixz="-7.97796107526925E-10" iyy="1.43894864274769E-05" iyz="3.44003507752819E-07" izz="1.4389503019841E-05" />
        </inertial>
        <visual>
            <origin rpy="0 0 0" xyz="0 0 0" />
            <geometry>
                <mesh filename="package://poll_arm_right/meshes/w1_link.STL" />
            </geometry>
            <material name="">
                <color rgba="0.792156862745098 0.819607843137255 0.933333333333333 1" />
            </material>
        </visual>
        <collision>
            <origin rpy="0 0 0" xyz="0 0 0" />
            <geometry>
                <mesh filename="package://poll_arm_right/meshes/w1_link.STL" />
            </geometry>
        </collision>
    </link>
    <joint name="stickbug/arm6/w1" type="revolute">
        <origin rpy="0 0 0" xyz="0.154351347 0 0.00586118891519596" />
        <parent link="stickbug/arm6/forearm" />
        <child link="stickbug/arm6/w1_link" />
        <axis xyz="0 0 1" />
        <limit effort="200" lower="-1.57" upper="1.57" velocity="0" />
        <dynamics damping="0.2" friction="0.2" />
    </joint>
    <link name="stickbug/arm6/w2_link">
        <inertial>
            <origin rpy="0 0 0" xyz="0.0566451733011976 -0.00141725658574912 0.0284323416048118" />
            <mass value="0.153757182920479" />
            <inertia ixx="9.61201704567482E-05" ixy="-2.53181854057694E-06" ixz="1.28235405708061E-05" iyy="0.000113585627853035" iyz="-2.70973268265225E-06" izz="6.51970121574257E-05" />
        </inertial>
        <visual>
            <origin rpy="0 0 0" xyz="0 0 0" />
            <geometry>
                <mesh filename="package://poll_arm_right/meshes/w2_link.STL" />
            </geometry>
            <material name="">
                <color rgba="0.792156862745098 0.819607843137255 0.933333333333333 1" />
            </material>
        </visual>
        <collision>
            <origin rpy="0 0 0" xyz="0 0 0" />
            <geometry>
                <mesh filename="package://poll_arm_right/meshes/w2_link.STL" />
            </geometry>
        </collision>
    </link>
    <joint name="stickbug/arm6/w2" type="revolute">
        <origin rpy="1.57079632679489 0 0" xyz="0.0240000007161376 0.0221999998475506 0.0221750001524488" />
        <parent link="stickbug/arm6/w1_link" />
        <child link="stickbug/arm6/w2_link" />
        <axis xyz="0 0 1" />
        <limit effort="200" lower="-1.57" upper="1.57" velocity="0" />
        <dynamics damping="0.2" friction="0.2" />
    </joint>
    <link name="stickbug/arm6/cam_link">
        <inertial>
            <origin rpy="0 0 0" xyz="-0.0113814657659484 -3.7765632954212E-08 -8.96828082674883E-05" />
            <mass value="0.0394840464043759" />
            <inertia ixx="1.13008734896739E-05" ixy="-1.18403271942562E-12" ixz="-1.11849815558335E-08" iyy="7.34442345562824E-06" iyz="2.14724251236641E-11" izz="7.39890475454631E-06" />
        </inertial>
        <visual>
            <origin rpy="0 0 0" xyz="0 0 0" />
            <geometry>
                <mesh filename="package://poll_arm_right/meshes/cam_link.STL" />
            </geometry>
            <material name="">
                <color rgba="0.792156862745098 0.819607843137255 0.933333333333333 1" />
            </material>
        </visual>
        <collision>
            <origin rpy="0 0 0" xyz="0 0 0" />
            <geometry>
                <mesh filename="package://poll_arm_right/meshes/cam_link.STL" />
            </geometry>
        </collision>
    </link>
    <joint name="stickbug/arm6/cam_joint" type="fixed">
        <origin rpy="0 0.26179938779915 0" xyz="0.063863151034262 0 0.0834316043147122" />
        <parent link="stickbug/arm6/w2_link" />
        <child link="stickbug/arm6/cam_link" />
        <axis xyz="0 0 0" />
    </joint>
    <link name="stickbug/arm6/e1_link">
        <inertial>
            <origin rpy="0 0 0" xyz="0.00768377159854672 0.00530600599131259 -0.000730992899423522" />
            <mass value="0.00225996756513805" />
            <inertia ixx="1.30412723697187E-07" ixy="9.73218559749733E-08" ixz="2.16169394663048E-08" iyy="1.966205244536E-07" iyz="-1.2986245459416E-08" izz="3.15647081687985E-07" />
        </inertial>
        <visual>
            <origin rpy="0 0 0" xyz="0 0 0" />
            <geometry>
                <mesh filename="package://poll_arm_right/meshes/e1_link.STL" />
            </geometry>
            <material name="">
                <color rgba="0.792156862745098 0.819607843137255 0.933333333333333 1" />
            </material>
        </visual>
        <collision>
            <origin rpy="0 0 0" xyz="0 0 0" />
            <geometry>
                <mesh filename="package://poll_arm_right/meshes/e1_link.STL" />
            </geometry>
        </collision>
    </link>
    <joint name="stickbug/arm6/e1" type="revolute">
        <origin rpy="-1.0471975511966 0 0" xyz="0.0769999999999999 0.0112634866641177 0.00700070249463941" />
        <parent link="stickbug/arm6/w2_link" />
        <child link="stickbug/arm6/e1_link" />
        <axis xyz="0 0 1" />
        <limit effort="200" lower="-1.57" upper="1.57" velocity="0" />
        <dynamics damping="0.2" friction="0.2" />
    </joint>
    <link name="stickbug/arm6/e2_link">
        <inertial>
            <origin rpy="0 0 0" xyz="0.0076837715993977 0.00530600599028458 -0.000730992897713667" />
            <mass value="0.00225996756505407" />
            <inertia ixx="1.30412723709295E-07" ixy="9.73218559904026E-08" ixz="2.16169394327849E-08" iyy="1.96620524444531E-07" iyz="-1.2986245443103E-08" izz="3.15647081713528E-07" />
        </inertial>
        <visual>
            <origin rpy="0 0 0" xyz="0 0 0" />
            <geometry>
                <mesh filename="package://poll_arm_right/meshes/e2_link.STL" />
            </geometry>
            <material name="">
                <color rgba="0.250980392156863 0.250980392156863 0.250980392156863 1" />
            </material>
        </visual>
        <collision>
            <origin rpy="0 0 0" xyz="0 0 0" />
            <geometry>
                <mesh filename="package://poll_arm_right/meshes/e2_link.STL" />
            </geometry>
        </collision>
    </link>
    <joint name="stickbug/arm6/e2" type="revolute">
        <origin rpy="1.0472 0 0" xyz="0.077 0.0074446 0.039404" />
        <parent link="stickbug/arm6/w2_link" />
        <child link="stickbug/arm6/e2_link" />
        <axis xyz="0 0 1" />
        <limit effort="200" lower="-1.57" upper="1.57" velocity="0" />
        <dynamics damping="0.2" friction="0.2" />
    </joint>
    <link name="stickbug/arm6/e3_link">
        <inertial>
            <origin rpy="0 0 0" xyz="0.00768377159880046 0.00530600599161379 -0.000730992902174266" />
            <mass value="0.00225996756527348" />
            <inertia ixx="1.30412723718879E-07" ixy="9.73218559573204E-08" ixz="2.16169395180174E-08" iyy="1.96620524429934E-07" iyz="-1.2986245490849E-08" izz="3.15647081641822E-07" />
        </inertial>
        <visual>
            <origin rpy="0 0 0" xyz="0 0 0" />
            <geometry>
                <mesh filename="package://poll_arm_right/meshes/e3_link.STL" />
            </geometry>
            <material name="">
                <color rgba="0.250980392156863 0.250980392156863 0.250980392156863 1" />
            </material>
        </visual>
        <collision>
            <origin rpy="0 0 0" xyz="0 0 0" />
            <geometry>
                <mesh filename="package://poll_arm_right/meshes/e3_link.STL" />
            </geometry>
        </collision>
    </link>
    <joint name="stickbug/arm6/e3" type="revolute">
        <origin rpy="3.14159265358979 0 0" xyz="0.077000000000051 -0.0187081185534836 0.0198951831632689" />
        <parent link="stickbug/arm6/w2_link" />
        <child link="stickbug/arm6/e3_link" />
        <axis xyz="0 0 1" />
        <limit effort="200" lower="-1.57" upper="1.57" velocity="0" />
        <dynamics damping="0.2" friction="0.2" />
    </joint>
    <link name="stickbug/arm6/end_link">
        <inertial>
            <origin rpy="0 0 0" xyz="-0.00224236893916036 -3.51872006532084E-08 3.59307923136765E-08" />
            <mass value="0.00244973338644466" />
            <inertia ixx="2.17281683587081E-07" ixy="1.95917302230901E-13" ixz="-3.07605742822788E-13" iyy="1.14231479742373E-07" iyz="9.90134628090014E-13" izz="1.14231411420647E-07" />
        </inertial>
        <visual>
            <origin rpy="0 0 0" xyz="0 0 0" />
            <geometry>
                <mesh filename="package://poll_arm_right/meshes/end_link.STL" />
            </geometry>
            <material name="">
                <color rgba="0.792156862745098 0.819607843137255 0.933333333333333 1" />
            </material>
        </visual>
        <collision>
            <origin rpy="0 0 0" xyz="0 0 0" />
            <geometry>
                <mesh filename="package://poll_arm_right/meshes/end_link.STL" />
            </geometry>
        </collision>
    </link>
    <joint name="stickbug/arm6/end_joint" type="fixed">
        <origin rpy="-1.57079632679491 0 0" xyz="0.122934886777477 0 0.0220999999985055" />
        <parent link="stickbug/arm6/w2_link" />
        <child link="stickbug/arm6/end_link" />
        <axis xyz="0 0 0" />
    </joint>
    <link name="stickbug/arm6/camera_frame" />
    <joint name="stickbug/arm6/cam_link2cam_frame" type="fixed">
        <parent link="stickbug/arm6/cam_link" />
        <child link="stickbug/arm6/camera_frame" />
        <origin rpy="-1.57 0.0 -1.57" xyz="0.0 0.0 0.0" />
    </joint>
    <transmission name="stickbug/arm6/trans_slider">
        <type>transmission_interface/SimpleTransmission</type>
        <joint name="stickbug/arm6/slider">
            <hardwareInterface>hardware_interface/EffortJointInterface</hardwareInterface>
        </joint>
        <actuator name="stickbug/arm6/slider_motor">
            <hardwareInterface>hardware_interface/EffortJointInterface</hardwareInterface>
            <mechanicalReduction>1</mechanicalReduction>
        </actuator>
    </transmission>
    <transmission name="stickbug/arm6/trans_shoulder">
        <type>transmission_interface/SimpleTransmission</type>
        <joint name="stickbug/arm6/shoulder">
            <hardwareInterface>hardware_interface/EffortJointInterface</hardwareInterface>
        </joint>
        <actuator name="stickbug/arm6/shoulder_motor">
            <hardwareInterface>hardware_interface/EffortJointInterface</hardwareInterface>
            <mechanicalReduction>1</mechanicalReduction>
        </actuator>
    </transmission>
    <transmission name="stickbug/arm6/trans_elbow">
        <type>transmission_interface/SimpleTransmission</type>
        <joint name="stickbug/arm6/elbow">
            <hardwareInterface>hardware_interface/EffortJointInterface</hardwareInterface>
        </joint>
        <actuator name="stickbug/arm6/elbow_motor">
            <hardwareInterface>hardware_interface/EffortJointInterface</hardwareInterface>
            <mechanicalReduction>1</mechanicalReduction>
        </actuator>
    </transmission>
    <transmission name="stickbug/arm6/trans_w1">
        <type>transmission_interface/SimpleTransmission</type>
        <joint name="stickbug/arm6/w1">
            <hardwareInterface>hardware_interface/EffortJointInterface</hardwareInterface>
        </joint>
        <actuator name="stickbug/arm6/w1_motor">
            <hardwareInterface>hardware_interface/EffortJointInterface</hardwareInterface>
            <mechanicalReduction>1</mechanicalReduction>
        </actuator>
    </transmission>
    <transmission name="stickbug/arm6/trans_w2">
        <type>transmission_interface/SimpleTransmission</type>
        <joint name="stickbug/arm6/w2">
            <hardwareInterface>hardware_interface/EffortJointInterface</hardwareInterface>
        </joint>
        <actuator name="stickbug/arm6/w2_motor">
            <hardwareInterface>hardware_interface/EffortJointInterface</hardwareInterface>
            <mechanicalReduction>1</mechanicalReduction>
        </actuator>
    </transmission>
    <transmission name="stickbug/arm6/trans_e1">
        <type>transmission_interface/SimpleTransmission</type>
        <joint name="stickbug/arm6/e1">
            <hardwareInterface>hardware_interface/EffortJointInterface</hardwareInterface>
        </joint>
        <actuator name="stickbug/arm6/e1_motor">
            <hardwareInterface>hardware_interface/EffortJointInterface</hardwareInterface>
            <mechanicalReduction>1</mechanicalReduction>
        </actuator>
    </transmission>
    <transmission name="stickbug/arm6/trans_e2">
        <type>transmission_interface/SimpleTransmission</type>
        <joint name="stickbug/arm6/e2">
            <hardwareInterface>hardware_interface/EffortJointInterface</hardwareInterface>
        </joint>
        <actuator name="stickbug/arm6/e2_motor">
            <hardwareInterface>hardware_interface/EffortJointInterface</hardwareInterface>
            <mechanicalReduction>1</mechanicalReduction>
        </actuator>
    </transmission>
    <transmission name="stickbug/arm6/trans_e3">
        <type>transmission_interface/SimpleTransmission</type>
        <joint name="stickbug/arm6/e3">
            <hardwareInterface>hardware_interface/EffortJointInterface</hardwareInterface>
        </joint>
        <actuator name="stickbug/arm6/e3_motor">
            <hardwareInterface>hardware_interface/EffortJointInterface</hardwareInterface>
            <mechanicalReduction>1</mechanicalReduction>
        </actuator>
    </transmission>
    <!--================================ right realsense plugin ================================-->
    <gazebo reference="stickbug/arm6/cam_link">
        <sensor name="stickbug/arm6/cam_link_camera" type="depth">
            <update_rate>20</update_rate>
            <camera>
                <horizontal_fov>1.047198</horizontal_fov>
                <image>
                    <width>640</width>
                    <height>480</height>
                    <format>R8G8B8</format>
                </image>
                <clip>
                    <near>0.05</near>
                    <far>3</far>
                </clip>
            </camera>
            <plugin filename="libgazebo_ros_openni_kinect.so" name="stickbug/arm6/cam_link_controller">
                <baseline>0.2</baseline>
                <alwaysOn>true</alwaysOn>
                <updateRate>1.0</updateRate>
                <cameraName>stickbug/arm6/cam_link</cameraName>
                <imageTopicName>color/image_raw</imageTopicName>
                <cameraInfoTopicName>color/camera_info</cameraInfoTopicName>
                <depthImageTopicName>depth/image_raw</depthImageTopicName>
                <depthImageInfoTopicName>depth/camera_info</depthImageInfoTopicName>
                <pointCloudTopicName>depth/points</pointCloudTopicName>
                <frameName>stickbug/arm6/camera_frame</frameName>
                <pointCloudCutoff>0.5</pointCloudCutoff>
                <pointCloudCutoffMax>3.0</pointCloudCutoffMax>
                <distortionK1>0.00000001</distortionK1>
                <distortionK2>0.00000001</distortionK2>
                <distortionK3>0.00000001</distortionK3>
                <distortionT1>0.00000001</distortionT1>
                <distortionT2>0.00000001</distortionT2>
                <CxPrime>0</CxPrime>
                <Cx>0</Cx>
                <Cy>0</Cy>
                <focalLength>0</focalLength>
                <hackBaseline>0</hackBaseline>
            </plugin>
        </sensor>
    </gazebo>
    <!-- top-level gazebo-ros interface-->
    <gazebo>
        <plugin filename="libgazebo_ros_control.so" name="gazebo_ros_control">
            <robotNamespace>/stickbug</robotNamespace>
            <robotSimType>gazebo_ros_control/DefaultRobotHWSim</robotSimType>
        </plugin>
    </gazebo>
</robot>

