<?xml version="1.0" encoding="utf-8"?>
<!-- This URDF was automatically created by SolidWorks to URDF Exporter! Originally created by Stephen Brawner (brawner@gmail.com) 
     Commit Version: 1.6.0-4-g7f85cfe  Build Version: 1.6.7995.38578
     For more information, please see http://wiki.ros.org/sw_urdf_exporter -->
<robot
  name="poll_arm_right" xmlns:xacro="http://ros.org/wiki/xacro">

  <xacro:include filename="$(find poll_arm_right)/urdf/poll_arm_right.gazebo.xacro" />

  <xacro:macro name="poll_arm_right" params="parent_link ns">
  
   

    <link
      name="${ns}/box">
      <inertial>
        <origin
          xyz="-0.0294836466854795 -0.00650699178978333 0.054665921342337"
          rpy="0 0 0" />
        <mass
          value="1.25224595398726" />
        <inertia
          ixx="0.00206596064394956"
          ixy="0.000334896166615364"
          ixz="-0.000136948453654299"
          iyy="0.0035115970252851"
          iyz="-4.17254634185766E-05"
          izz="0.00431158338218049" />
      </inertial>
      <visual>
        <origin
          xyz="0 0 0"
          rpy="0 0 0" />
        <geometry>
          <mesh
            filename="package://poll_arm_right/meshes/box.STL" />
        </geometry>
        <material
          name="">
          <color
            rgba="0.792156862745098 0.819607843137255 0.933333333333333 1" />
        </material>
      </visual>
      <collision>
        <origin
          xyz="0 0 0"
          rpy="0 0 0" />
        <geometry>
          <mesh
            filename="package://poll_arm_right/meshes/box.STL" />
        </geometry>
      </collision>
    </link>
    <joint
      name="${ns}/slider"
      type="prismatic">
      <origin
        xyz="0 0 0"
        rpy="0 0 0" />
      <parent
        link="${parent_link}" />
      <child
        link="${ns}/box" />
      <axis
        xyz="0 0 1" />
      <limit
        lower="0"
        upper="2"
        effort="200"
        velocity="0" />
      <dynamics
        damping="0.2"
        friction="0.2" />
    </joint>
    <link
      name="${ns}/bicep">
      <inertial>
        <origin
          xyz="0.19577236492752 0.025617006022445 0.031470242482028"
          rpy="0 0 0" />
        <mass
          value="0.0881583450015477" />
        <inertia
          ixx="4.02190655717306E-05"
          ixy="-9.41441514101079E-09"
          ixz="-4.66388635592039E-08"
          iyy="2.35490419805005E-05"
          iyz="-9.36030697866667E-08"
          izz="3.32834464790013E-05" />
      </inertial>
      <visual>
        <origin
          xyz="0 0 0"
          rpy="0 0 0" />
        <geometry>
          <mesh
            filename="package://poll_arm_right/meshes/bicep.STL" />
        </geometry>
        <material
          name="">
          <color
            rgba="0.698039215686274 0.698039215686274 0.698039215686274 1" />
        </material>
      </visual>
      <collision>
        <origin
          xyz="0 0 0"
          rpy="0 0 0" />
        <geometry>
          <mesh
            filename="package://poll_arm_right/meshes/bicep.STL" />
        </geometry>
      </collision>
    </link>
    <joint
      name="${ns}/shoulder"
      type="revolute">
      <origin
        xyz="0.101983673651571 -0.0444010956927517 0.0186529999998991"
        rpy="0 0 -0.523598775598304" />
      <parent
        link="${ns}/box" />
      <child
        link="${ns}/bicep" />
      <axis
        xyz="0 0 1" />
      <limit
        lower="-1.57"
        upper="1.57"
        effort="200"
        velocity="0" />
      <dynamics
        damping="0.2"
        friction="0.2" />
    </joint>
    <link
      name="${ns}/forearm">
      <inertial>
        <origin
          xyz="0.0765243373190801 -0.00763087662935313 0.0278615390492158"
          rpy="0 0 0" />
        <mass
          value="0.0881583450015477" />
        <inertia
          ixx="4.02190655717306E-05"
          ixy="-9.41441514101079E-09"
          ixz="-4.66388635592039E-08"
          iyy="2.35490419805005E-05"
          iyz="-9.36030697866667E-08"
          izz="3.32834464790013E-05" />
      </inertial>
      <visual>
        <origin
          xyz="0 0 0"
          rpy="0 0 0" />
        <geometry>
          <mesh
            filename="package://poll_arm_right/meshes/forearm.STL" />
        </geometry>
        <material
          name="">
          <color
            rgba="0.698039215686274 0.698039215686274 0.698039215686274 1" />
        </material>
      </visual>
      <collision>
        <origin
          xyz="0 0 0"
          rpy="0 0 0" />
        <geometry>
          <mesh
            filename="package://poll_arm_right/meshes/forearm.STL" />
        </geometry>
      </collision>
    </link>
    <joint
      name="${ns}/elbow"
      type="revolute">
      <origin
        xyz="0.1959 0.0406860000000015 0.00350608116532053"
        rpy="0 0 1.5707963267949" />
      <parent
        link="${ns}/bicep" />
      <child
        link="${ns}/forearm" />
      <axis
        xyz="0 0 1" />
      <limit
        lower="-1.57"
        upper="1.57"
        effort="200"
        velocity="0" />
      <dynamics
        damping="0.2"
        friction="0.2" />
    </joint>
    <link
      name="${ns}/w1_link">
      <inertial>
        <origin
          xyz="0.0119998492953422 -0.000549087822445449 0.0216260058358662"
          rpy="0 0 0" />
        <mass
          value="0.0565320862795783" />
        <inertia
          ixx="1.0226625085126E-05"
          ixy="6.10475234160948E-10"
          ixz="-7.97796107526925E-10"
          iyy="1.43894864274769E-05"
          iyz="3.44003507752819E-07"
          izz="1.4389503019841E-05" />
      </inertial>
      <visual>
        <origin
          xyz="0 0 0"
          rpy="0 0 0" />
        <geometry>
          <mesh
            filename="package://poll_arm_right/meshes/w1_link.STL" />
        </geometry>
        <material
          name="">
          <color
            rgba="0.792156862745098 0.819607843137255 0.933333333333333 1" />
        </material>
      </visual>
      <collision>
        <origin
          xyz="0 0 0"
          rpy="0 0 0" />
        <geometry>
          <mesh
            filename="package://poll_arm_right/meshes/w1_link.STL" />
        </geometry>
      </collision>
    </link>
    <joint
      name="${ns}/w1"
      type="revolute">
      <origin
        xyz="0.154351347 0 0.00586118891519596"
        rpy="0 0 0" />
      <parent
        link="${ns}/forearm" />
      <child
        link="${ns}/w1_link" />
      <axis
        xyz="0 0 1" />
      <limit
        lower="-1.57"
        upper="1.57"
        effort="200"
        velocity="0" />
      <dynamics
        damping="0.2"
        friction="0.2" />
    </joint>
    <link
      name="${ns}/w2_link">
      <inertial>
        <origin
          xyz="0.0566451733011976 -0.00141725658574912 0.0284323416048118"
          rpy="0 0 0" />
        <mass
          value="0.153757182920479" />
        <inertia
          ixx="9.61201704567482E-05"
          ixy="-2.53181854057694E-06"
          ixz="1.28235405708061E-05"
          iyy="0.000113585627853035"
          iyz="-2.70973268265225E-06"
          izz="6.51970121574257E-05" />
      </inertial>
      <visual>
        <origin
          xyz="0 0 0"
          rpy="0 0 0" />
        <geometry>
          <mesh
            filename="package://poll_arm_right/meshes/w2_link.STL" />
        </geometry>
        <material
          name="">
          <color
            rgba="0.792156862745098 0.819607843137255 0.933333333333333 1" />
        </material>
      </visual>
      <collision>
        <origin
          xyz="0 0 0"
          rpy="0 0 0" />
        <geometry>
          <mesh
            filename="package://poll_arm_right/meshes/w2_link.STL" />
        </geometry>
      </collision>
    </link>
    <joint
      name="${ns}/w2"
      type="revolute">
      <origin
        xyz="0.0240000007161376 0.0221999998475506 0.0221750001524488"
        rpy="1.57079632679489 0 0" />
      <parent
        link="${ns}/w1_link" />
      <child
        link="${ns}/w2_link" />
      <axis
        xyz="0 0 1" />
      <limit
        lower="-1.57"
        upper="1.57"
        effort="200"
        velocity="0" />
      <dynamics
        damping="0.2"
        friction="0.2" />
    </joint>
    <link
      name="${ns}/cam_link">
      <inertial>
        <origin
          xyz="-0.0113814657659484 -3.7765632954212E-08 -8.96828082674883E-05"
          rpy="0 0 0" />
        <mass
          value="0.0394840464043759" />
        <inertia
          ixx="1.13008734896739E-05"
          ixy="-1.18403271942562E-12"
          ixz="-1.11849815558335E-08"
          iyy="7.34442345562824E-06"
          iyz="2.14724251236641E-11"
          izz="7.39890475454631E-06" />
      </inertial>
      <visual>
        <origin
          xyz="0 0 0"
          rpy="0 0 0" />
        <geometry>
          <mesh
            filename="package://poll_arm_right/meshes/cam_link.STL" />
        </geometry>
        <material
          name="">
          <color
            rgba="0.792156862745098 0.819607843137255 0.933333333333333 1" />
        </material>
      </visual>
      <collision>
        <origin
          xyz="0 0 0"
          rpy="0 0 0" />
        <geometry>
          <mesh
            filename="package://poll_arm_right/meshes/cam_link.STL" />
        </geometry>
      </collision>
    </link>
    <joint
      name="${ns}/cam_joint"
      type="fixed">
      <origin
        xyz="0.063863151034262 0 0.0834316043147122"
        rpy="0 0.26179938779915 0" />
      <parent
        link="${ns}/w2_link" />
      <child
        link="${ns}/cam_link" />
      <axis
        xyz="0 0 0" />
    </joint>
    <link
      name="${ns}/e1_link">
      <inertial>
        <origin
          xyz="0.00768377159854672 0.00530600599131259 -0.000730992899423522"
          rpy="0 0 0" />
        <mass
          value="0.00225996756513805" />
        <inertia
          ixx="1.30412723697187E-07"
          ixy="9.73218559749733E-08"
          ixz="2.16169394663048E-08"
          iyy="1.966205244536E-07"
          iyz="-1.2986245459416E-08"
          izz="3.15647081687985E-07" />
      </inertial>
      <visual>
        <origin
          xyz="0 0 0"
          rpy="0 0 0" />
        <geometry>
          <mesh
            filename="package://poll_arm_right/meshes/e1_link.STL" />
        </geometry>
        <material
          name="">
          <color
            rgba="0.792156862745098 0.819607843137255 0.933333333333333 1" />
        </material>
      </visual>
      <collision>
        <origin
          xyz="0 0 0"
          rpy="0 0 0" />
        <geometry>
          <mesh
            filename="package://poll_arm_right/meshes/e1_link.STL" />
        </geometry>
      </collision>
    </link>
    <joint
      name="${ns}/e1"
      type="revolute">
      <origin
        xyz="0.0769999999999999 0.0112634866641177 0.00700070249463941"
        rpy="-1.0471975511966 0 0" />
      <parent
        link="${ns}/w2_link" />
      <child
        link="${ns}/e1_link" />
      <axis
        xyz="0 0 1" />
      <limit
        lower="-1.57"
        upper="1.57"
        effort="200"
        velocity="0" />
      <dynamics
        damping="0.2"
        friction="0.2" />
    </joint>
    <link
      name="${ns}/e2_link">
      <inertial>
        <origin
          xyz="0.0076837715993977 0.00530600599028458 -0.000730992897713667"
          rpy="0 0 0" />
        <mass
          value="0.00225996756505407" />
        <inertia
          ixx="1.30412723709295E-07"
          ixy="9.73218559904026E-08"
          ixz="2.16169394327849E-08"
          iyy="1.96620524444531E-07"
          iyz="-1.2986245443103E-08"
          izz="3.15647081713528E-07" />
      </inertial>
      <visual>
        <origin
          xyz="0 0 0"
          rpy="0 0 0" />
        <geometry>
          <mesh
            filename="package://poll_arm_right/meshes/e2_link.STL" />
        </geometry>
        <material
          name="">
          <color
            rgba="0.250980392156863 0.250980392156863 0.250980392156863 1" />
        </material>
      </visual>
      <collision>
        <origin
          xyz="0 0 0"
          rpy="0 0 0" />
        <geometry>
          <mesh
            filename="package://poll_arm_right/meshes/e2_link.STL" />
        </geometry>
      </collision>
    </link>
    <joint
      name="${ns}/e2"
      type="revolute">
      <origin
        xyz="0.077 0.0074446 0.039404"
        rpy="1.0472 0 0" />
      <parent
        link="${ns}/w2_link" />
      <child
        link="${ns}/e2_link" />
      <axis
        xyz="0 0 1" />
      <limit
        lower="-1.57"
        upper="1.57"
        effort="200"
        velocity="0" />
      <dynamics
        damping="0.2"
        friction="0.2" />
    </joint>
    <link
      name="${ns}/e3_link">
      <inertial>
        <origin
          xyz="0.00768377159880046 0.00530600599161379 -0.000730992902174266"
          rpy="0 0 0" />
        <mass
          value="0.00225996756527348" />
        <inertia
          ixx="1.30412723718879E-07"
          ixy="9.73218559573204E-08"
          ixz="2.16169395180174E-08"
          iyy="1.96620524429934E-07"
          iyz="-1.2986245490849E-08"
          izz="3.15647081641822E-07" />
      </inertial>
      <visual>
        <origin
          xyz="0 0 0"
          rpy="0 0 0" />
        <geometry>
          <mesh
            filename="package://poll_arm_right/meshes/e3_link.STL" />
        </geometry>
        <material
          name="">
          <color
            rgba="0.250980392156863 0.250980392156863 0.250980392156863 1" />
        </material>
      </visual>
      <collision>
        <origin
          xyz="0 0 0"
          rpy="0 0 0" />
        <geometry>
          <mesh
            filename="package://poll_arm_right/meshes/e3_link.STL" />
        </geometry>
      </collision>
    </link>
    <joint
      name="${ns}/e3"
      type="revolute">
      <origin
        xyz="0.077000000000051 -0.0187081185534836 0.0198951831632689"
        rpy="3.14159265358979 0 0" />
      <parent
        link="${ns}/w2_link" />
      <child
        link="${ns}/e3_link" />
      <axis
        xyz="0 0 1" />
      <limit
        lower="-1.57"
        upper="1.57"
        effort="200"
        velocity="0" />
      <dynamics
        damping="0.2"
        friction="0.2" />
    </joint>
    <link
      name="${ns}/end_link">
      <inertial>
        <origin
          xyz="-0.00224236893916036 -3.51872006532084E-08 3.59307923136765E-08"
          rpy="0 0 0" />
        <mass
          value="0.00244973338644466" />
        <inertia
          ixx="2.17281683587081E-07"
          ixy="1.95917302230901E-13"
          ixz="-3.07605742822788E-13"
          iyy="1.14231479742373E-07"
          iyz="9.90134628090014E-13"
          izz="1.14231411420647E-07" />
      </inertial>
      <visual>
        <origin
          xyz="0 0 0"
          rpy="0 0 0" />
        <geometry>
          <mesh
            filename="package://poll_arm_right/meshes/end_link.STL" />
        </geometry>
        <material
          name="">
          <color
            rgba="0.792156862745098 0.819607843137255 0.933333333333333 1" />
        </material>
      </visual>
      <collision>
        <origin
          xyz="0 0 0"
          rpy="0 0 0" />
        <geometry>
          <mesh
            filename="package://poll_arm_right/meshes/end_link.STL" />
        </geometry>
      </collision>
    </link>
    <joint
      name="${ns}/end_joint"
      type="fixed">
      <origin
        xyz="0.122934886777477 0 0.0220999999985055"
        rpy="-1.57079632679491 0 0" />
      <parent
        link="${ns}/w2_link" />
      <child
        link="${ns}/end_link" />
      <axis
        xyz="0 0 0" />
    </joint>

    <link name="${ns}/camera_frame"/>
    <joint
  	name="${ns}/cam_link2cam_frame"
  	type="fixed">
  	<parent link="${ns}/cam_link"/>
  	<child link="${ns}/camera_frame"/>
    <origin
      xyz="0.0 0.0 0.0"
      rpy="-1.57 0.0 -1.57" />
  </joint>

    <xacro:poll_arm_right_gazebo ns="${ns}"/>

  </xacro:macro>

</robot>